Workbook

Sheet armorBaseData(read)
B1: lookup_Series | C1: lookup_Armor | D1: 模型编号 | E1: Lv1SlotNum | F1: Lv2SlotNum | G1: Lv3SlotNum | H1: Lv4SlotNum | I1: SkillLookUp[0] | J1: SkillLV[0] | K1: SkillLookUp[1] | L1: SkillLV[1] | M1: SkillLookUp[2] | N1: SkillLV[2] | O1: SkillLookUp[3] | P1: SkillLV[3] | Q1: SkillLookUp[4] | R1: SkillLV[4] | S1: 词条池 | T1: Cost
A2: 1 | B2: 炎火装束 | C2: 炎火装束【头巾】 | D2: pl200 | E2: 0 | F2: 0 | G2: 0 | H2: 0 | I2: 精灵加护 | J2: 1 | L2: 0 | N2: 0 | P2: 0 | R2: 0 | S2: 0 | T2: 0
A3: 2 | B3: 炎火装束 | C3: 炎火装束【上衣】 | D3: pl200 | E3: 0 | F3: 0 | G3: 0 | H3: 0 | I3: 翔虫使 | J3: 1 | L3: 0 | N3: 0 | P3: 0 | R3: 0 | S3: 0 | T3: 0
A4: 3 | B4: 炎火装束 | C4: 炎火装束【手甲】 | D4: pl200 | E4: 0 | F4: 0 | G4: 0 | H4: 0 | I4: 火场怪力 | J4: 1 | L4: 0 | N4: 0 | P4: 0 | R4: 0 | S4: 0 | T4: 0
A5: 4 | B5: 炎火装束 | C5: 炎火装束【腰卷】 | D5: pl200 | E5: 0 | F5: 0 | G5: 0 | H5: 0 | I5: 看破 | J5: 1 | L5: 0 | N5: 0 | P5: 0 | R5: 0 | S5: 0 | T5: 0
A6: 5 | B6: 炎火装束 | C6: 炎火装束【绑腿】 | D6: pl200 | E6: 0 | F6: 0 | G6: 0 | H6: 0 | I6: 墙面移动 | J6: 1 | L6: 0 | N6: 0 | P6: 0 | R6: 0 | S6: 0 | T6: 0
A7: 1 | B7: 炎火装束・霸 | C7: 炎火装束【头巾】霸 | D7: pl200 | E7: 1 | F7: 0 | G7: 0 | H7: 0 | I7: 精灵加护 | J7: 1 | K7: 死里逃生 | L7: 1 | N7: 0 | P7: 0 | R7: 0 | S7: 0 | T7: 0
A8: 2 | B8: 炎火装束・霸 | C8: 炎火装束【上衣】霸 | D8: pl200 | E8: 1 | F8: 0 | G8: 0 | H8: 0 | I8: 翔虫使 | J8: 2 | K8: 墙面移动 | L8: 1 | M8: 看破 | N8: 1 | P8: 0 | R8: 0 | S8: 0 | T8: 0
A9: 3 | B9: 炎火装束・霸 | C9: 炎火装束【手甲】霸 | D9: pl200 | E9: 0 | F9: 1 | G9: 0 | H9: 0 | I9: 看破 | J9: 2 | K9: 火场怪力 | L9: 1 | N9: 0 | P9: 0 | R9: 0 | S9: 0 | T9: 0
A10: 4 | B10: 炎火装束・霸 | C10: 炎火装束【腰卷】霸 | D10: pl200 | E10: 2 | F10: 0 | G10: 0 | H10: 0 | I10: 翔虫使 | J10: 1 | K10: 看破 | L10: 1 | N10: 0 | P10: 0 | R10: 0 | S10: 0 | T10: 0
A11: 5 | B11: 炎火装束・霸 | C11: 炎火装束【绑腿】霸 | D11: pl200 | E11: 1 | F11: 0 | G11: 0 | H11: 0 | I11: 墙面移动 | J11: 2 | K11: 死里逃生 | L11: 1 | N11: 0 | P11: 0 | R11: 0 | S11: 0 | T11: 0
A12: 1 | B12: 皮制 | C12: 皮制头饰 | D12: pl001 | E12: 0 | F12: 0 | G12: 0 | H12: 0 | I12: 饥饿耐性 | J12: 1 | L12: 0 | N12: 0 | P12: 0 | R12: 0 | S12: 0 | T12: 0
A13: 2 | B13: 皮制 | C13: 皮制服饰 | D13: pl001 | E13: 0 | F13: 0 | G13: 0 | H13: 0 | I13: 植生学 | J13: 1 | L13: 0 | N13: 0 | P13: 0 | R13: 0 | S13: 0 | T13: 0
A14: 3 | B14: 皮制 | C14: 皮制手套 | D14: pl001 | E14: 0 | F14: 0 | G14: 0 | H14: 0 | I14: 地质学 | J14: 1 | L14: 0 | N14: 0 | P14: 0 | R14: 0 | S14: 0 | T14: 0
A15: 4 | B15: 皮制 | C15: 皮制腰带 | D15: pl001 | E15: 0 | F15: 0 | G15: 0 | H15: 0 | I15: 体力回复量提升 | J15: 1 | L15: 0 | N15: 0 | P15: 0 | R15: 0 | S15: 0 | T15: 0
A16: 5 | B16: 皮制 | C16: 皮制长裤 | D16: pl001 | E16: 0 | F16: 0 | G16: 0 | H16: 0 | I16: 地质学 | J16: 1 | L16: 0 | N16: 0 | P16: 0 | R16: 0 | S16: 0 | T16: 0
A17: 1 | B17: 皮制S | C17: 皮制S头饰 | D17: pl001 | E17: 2 | F17: 0 | G17: 0 | H17: 0 | I17: 地质学 | J17: 1 | K17: 饥饿耐性 | L17: 1 | N17: 0 | P17: 0 | R17: 0 | S17: 0 | T17: 0
A18: 2 | B18: 皮制S | C18: 皮制S服饰 | D18: pl001 | E18: 0 | F18: 1 | G18: 0 | H18: 0 | I18: 植生学 | J18: 1 | L18: 0 | N18: 0 | P18: 0 | R18: 0 | S18: 0 | T18: 0
A19: 3 | B19: 皮制S | C19: 皮制S手套 | D19: pl001 | E19: 2 | F19: 0 | G19: 0 | H19: 0 | I19: 地质学 | J19: 1 | K19: 特殊射击强化 | L19: 1 | N19: 0 | P19: 0 | R19: 0 | S19: 0 | T19: 0
A20: 4 | B20: 皮制S | C20: 皮制S腰带 | D20: pl001 | E20: 1 | F20: 0 | G20: 0 | H20: 0 | I20: 体力回复量提升 | J20: 1 | K20: 饥饿耐性 | L20: 2 | N20: 0 | P20: 0 | R20: 0 | S20: 0 | T20: 0
A21: 5 | B21: 皮制S | C21: 皮制S长裤 | D21: pl001 | E21: 0 | F21: 1 | G21: 0 | H21: 0 | I21: 地质学 | J21: 1 | L21: 0 | N21: 0 | P21: 0 | R21: 0 | S21: 0 | T21: 0
A22: 1 | B22: 锁甲 | C22: 锁甲头饰 | D22: pl014 | E22: 0 | F22: 0 | G22: 0 | H22: 0 | I22: 植生学 | J22: 1 | K22: 防御 | L22: 1 | N22: 0 | P22: 0 | R22: 0 | S22: 0 | T22: 0
A23: 2 | B23: 锁甲 | C23: 锁甲服饰 | D23: pl014 | E23: 0 | F23: 0 | G23: 0 | H23: 0 | I23: 无伤 | J23: 1 | K23: 防御 | L23: 1 | N23: 0 | P23: 0 | R23: 0 | S23: 0 | T23: 0
A24: 3 | B24: 锁甲 | C24: 锁甲手套 | D24: pl014 | E24: 0 | F24: 0 | G24: 0 | H24: 0 | I24: 植生学 | J24: 1 | L24: 0 | N24: 0 | P24: 0 | R24: 0 | S24: 0 | T24: 0
A25: 4 | B25: 锁甲 | C25: 锁甲腰带 | D25: pl014 | E25: 0 | F25: 0 | G25: 0 | H25: 0 | I25: 防御性能 | J25: 1 | L25: 0 | N25: 0 | P25: 0 | R25: 0 | S25: 0 | T25: 0
A26: 5 | B26: 锁甲 | C26: 锁甲长裤 | D26: pl014 | E26: 0 | F26: 0 | G26: 0 | H26: 0 | I26: 耐力急速回复 | J26: 1 | L26: 0 | N26: 0 | P26: 0 | R26: 0 | S26: 0 | T26: 0
A27: 1 | B27: 锁甲S | C27: 锁甲S头饰 | D27: pl014 | E27: 0 | F27: 1 | G27: 0 | H27: 0 | I27: 植生学 | J27: 1 | K27: 防御 | L27: 1 | N27: 0 | P27: 0 | R27: 0 | S27: 0 | T27: 0
A28: 2 | B28: 锁甲S | C28: 锁甲S服饰 | D28: pl014 | E28: 1 | F28: 0 | G28: 0 | H28: 0 | I28: 防御 | J28: 1 | K28: 减轻胆怯 | L28: 2 | N28: 0 | P28: 0 | R28: 0 | S28: 0 | T28: 0
A29: 3 | B29: 锁甲S | C29: 锁甲S手套 | D29: pl014 | E29: 2 | F29: 0 | G29: 0 | H29: 0 | I29: 植生学 | J29: 1 | K29: 防御 | L29: 2 | N29: 0 | P29: 0 | R29: 0 | S29: 0 | T29: 0
A30: 4 | B30: 锁甲S | C30: 锁甲S腰带 | D30: pl014 | E30: 2 | F30: 0 | G30: 0 | H30: 0 | I30: 植生学 | J30: 1 | K30: 防御性能 | L30: 1 | N30: 0 | P30: 0 | R30: 0 | S30: 0 | T30: 0
A31: 5 | B31: 锁甲S | C31: 锁甲S长裤 | D31: pl014 | E31: 2 | F31: 0 | G31: 0 | H31: 0 | I31: 植生学 | J31: 1 | K31: 耐力急速回复 | L31: 1 | N31: 0 | P31: 0 | R31: 0 | S31: 0 | T31: 0
A32: 1 | B32: 猎人 | C32: 猎人头盔 | D32: pl002 | E32: 0 | F32: 0 | G32: 0 | H32: 0 | I32: 道具使用强化 | J32: 1 | L32: 0 | N32: 0 | P32: 0 | R32: 0 | S32: 0 | T32: 0
A33: 2 | B33: 猎人 | C33: 猎人铠甲 | D33: pl002 | E33: 0 | F33: 0 | G33: 0 | H33: 0 | I33: 攻击 | J33: 1 | L33: 0 | N33: 0 | P33: 0 | R33: 0 | S33: 0 | T33: 0
A34: 3 | B34: 猎人 | C34: 猎人腕甲 | D34: pl002 | E34: 0 | F34: 0 | G34: 0 | H34: 0 | I34: 纳刀术 | J34: 1 | L34: 0 | N34: 0 | P34: 0 | R34: 0 | S34: 0 | T34: 0
A35: 4 | B35: 猎人 | C35: 猎人腰甲 | D35: pl002 | E35: 0 | F35: 0 | G35: 0 | H35: 0 | I35: 昏厥耐性 | J35: 1 | L35: 0 | N35: 0 | P35: 0 | R35: 0 | S35: 0 | T35: 0
A36: 5 | B36: 猎人 | C36: 猎人护腿 | D36: pl002 | E36: 0 | F36: 0 | G36: 0 | H36: 0 | I36: 昏厥耐性 | J36: 1 | K36: 攻击 | L36: 1 | N36: 0 | P36: 0 | R36: 0 | S36: 0 | T36: 0
A37: 1 | B37: 猎人S | C37: 猎人S头盔 | D37: pl002 | E37: 0 | F37: 1 | G37: 0 | H37: 0 | I37: 道具使用强化 | J37: 1 | L37: 0 | N37: 0 | P37: 0 | R37: 0 | S37: 0 | T37: 0
A38: 2 | B38: 猎人S | C38: 猎人S铠甲 | D38: pl002 | E38: 1 | F38: 0 | G38: 0 | H38: 0 | I38: 攻击 | J38: 1 | K38: 匠 | L38: 1 | N38: 0 | P38: 0 | R38: 0 | S38: 0 | T38: 0
A39: 3 | B39: 猎人S | C39: 猎人S腕甲 | D39: pl002 | E39: 0 | F39: 1 | G39: 0 | H39: 0 | I39: 纳刀术 | J39: 1 | L39: 0 | N39: 0 | P39: 0 | R39: 0 | S39: 0 | T39: 0
A40: 4 | B40: 猎人S | C40: 猎人S腰甲 | D40: pl002 | E40: 2 | F40: 0 | G40: 0 | H40: 0 | I40: 昏厥耐性 | J40: 2 | L40: 0 | N40: 0 | P40: 0 | R40: 0 | S40: 0 | T40: 0
...

Sheet 看我
A1: 关于M位技能，请参考 | B1: https://ngabbs.com/read.php?tid=32376852&_ff=489&page=e#pid619245540Anchor
A2: 关于4级孔，请参考 | B2: https://ngabbs.com/read.php?tid=32373952
A5: Lv1SlotNum | B5: Lv2SlotNum | C5: Lv3SlotNum | D5: Lv4SlotNum
A6: 这个是一级孔的“数量” | B6: 这个是二级孔的“数量” | C6: 这个是三级孔的“数量” | D6: 这个四级孔的“数量”
A8: 10.0.2对比10.0.1没有变化
A9: 【腾讯文档】dtlnor rise sunbreak乱七八糟数据合集
A10: dtlnor rise sunbreak乱七八糟数据合集

Sheet 最大防御
B1: lookup_Series | C1: lookup_Armor | D1: DefVal | E1: BuildupTable | F1: 最大防御 | G1: parseArmorId | H1: Id | I1: IsValid | J1: Series | K1: SortId | L1: ModelId | M1: Rare | N1: Value | O1: BuyValue | P1: SexualEquipable | Q1: SymbolColor1 | R1: SymbolColor2 | S1: FireRegVal | T1: WaterRegVal | U1: IceRegVal | V1: ThunderRegVal | W1: DragonRegVal | X1: BuffFormula | Y1: Lv1SlotNum | Z1: Lv2SlotNum | AA1: Lv3SlotNum | AB1: SkillList[0] | AC1: SkillList[1] | AD1: SkillList[2] | AE1: SkillList[3] | AF1: SkillList[4] | AG1: SkillLvList[0] | AH1: SkillLvList[1] | AI1: SkillLvList[2] | AJ1: SkillLvList[3] | AK1: SkillLvList[4] | AL1: IdAfterExChange
A2: 1 | B2: =IF(I2=0,"",VLOOKUP(J2,seriesName!A:B,2,TRUE)) -> 炎火装束 | C2: 炎火装束【头巾】 | D2: 1 | E2: 0 | F2: =D2+VLOOKUP(E2,BuildupTable!L:O,4,FALSE) -> 67 | G2: 0 | H2: 0x0C100000 | I2: 1 | J2: 0 | K2: 1001 | L2: 30 | M2: 0 | N2: 100 | O2: 300 | P2: 2 | Q2: 0 | R2: 0 | S2: 1 | T2: 0 | U2: 0 | V2: 0 | W2: 0 | X2: 0 | Y2: 0 | Z2: 0 | AA2: 0 | AB2: 57 | AC2: 0 | AD2: 0 | AE2: 0 | AF2: 0 | AG2: 1 | AH2: 0 | AI2: 0 | AJ2: 0 | AK2: 0 | AL2: 0x00000000
A3: 2 | B3: =IF(I3=0,"",VLOOKUP(J3,seriesName!A:B,2,TRUE)) -> 炎火装束 | C3: 炎火装束【上衣】 | D3: 1 | E3: 0 | F3: =D3+VLOOKUP(E3,BuildupTable!L:O,4,FALSE) -> 67 | G3: 0 | H3: 0x0C200000 | I3: 1 | J3: 0 | K3: 1001 | L3: 30 | M3: 0 | N3: 100 | O3: 300 | P3: 2 | Q3: 0 | R3: 0 | S3: 1 | T3: 0 | U3: 0 | V3: 0 | W3: 0 | X3: 0 | Y3: 0 | Z3: 0 | AA3: 0 | AB3: 104 | AC3: 0 | AD3: 0 | AE3: 0 | AF3: 0 | AG3: 1 | AH3: 0 | AI3: 0 | AJ3: 0 | AK3: 0 | AL3: 0x00000000
A4: 3 | B4: =IF(I4=0,"",VLOOKUP(J4,seriesName!A:B,2,TRUE)) -> 炎火装束 | C4: 炎火装束【手甲】 | D4: 1 | E4: 0 | F4: =D4+VLOOKUP(E4,BuildupTable!L:O,4,FALSE) -> 67 | G4: 0 | H4: 0x0C300000 | I4: 1 | J4: 0 | K4: 1001 | L4: 30 | M4: 0 | N4: 100 | O4: 300 | P4: 2 | Q4: 0 | R4: 0 | S4: 1 | T4: 0 | U4: 0 | V4: 0 | W4: 0 | X4: 0 | Y4: 0 | Z4: 0 | AA4: 0 | AB4: 91 | AC4: 0 | AD4: 0 | AE4: 0 | AF4: 0 | AG4: 1 | AH4: 0 | AI4: 0 | AJ4: 0 | AK4: 0 | AL4: 0x00000000
A5: 4 | B5: =IF(I5=0,"",VLOOKUP(J5,seriesName!A:B,2,TRUE)) -> 炎火装束 | C5: 炎火装束【腰卷】 | D5: 1 | E5: 0 | F5: =D5+VLOOKUP(E5,BuildupTable!L:O,4,FALSE) -> 67 | G5: 0 | H5: 0x0C400000 | I5: 1 | J5: 0 | K5: 1001 | L5: 30 | M5: 0 | N5: 100 | O5: 300 | P5: 2 | Q5: 0 | R5: 0 | S5: 1 | T5: 0 | U5: 0 | V5: 0 | W5: 0 | X5: 0 | Y5: 0 | Z5: 0 | AA5: 0 | AB5: 6 | AC5: 0 | AD5: 0 | AE5: 0 | AF5: 0 | AG5: 1 | AH5: 0 | AI5: 0 | AJ5: 0 | AK5: 0 | AL5: 0x00000000
A6: 5 | B6: =IF(I6=0,"",VLOOKUP(J6,seriesName!A:B,2,TRUE)) -> 炎火装束 | C6: 炎火装束【绑腿】 | D6: 1 | E6: 0 | F6: =D6+VLOOKUP(E6,BuildupTable!L:O,4,FALSE) -> 67 | G6: 0 | H6: 0x0C500000 | I6: 1 | J6: 0 | K6: 1001 | L6: 30 | M6: 0 | N6: 100 | O6: 300 | P6: 2 | Q6: 0 | R6: 0 | S6: 1 | T6: 0 | U6: 0 | V6: 0 | W6: 0 | X6: 0 | Y6: 0 | Z6: 0 | AA6: 0 | AB6: 105 | AC6: 0 | AD6: 0 | AE6: 0 | AF6: 0 | AG6: 1 | AH6: 0 | AI6: 0 | AJ6: 0 | AK6: 0 | AL6: 0x00000000
A7: 1 | B7: =IF(I7=0,"",VLOOKUP(J7,seriesName!A:B,2,TRUE)) -> 炎火装束・霸 | C7: 炎火装束【头巾】霸 | D7: 30 | E7: 6 | F7: =D7+VLOOKUP(E7,BuildupTable!L:O,4,FALSE) -> 30 | G7: 1 | H7: 0x0C100001 | I7: 1 | J7: 1 | K7: 8001 | L7: 30 | M7: 3 | N7: 4000 | O7: 12000 | P7: 2 | Q7: 1 | R7: 1 | S7: 2 | T7: 0 | U7: 0 | V7: 0 | W7: 0 | X7: 0 | Y7: 1 | Z7: 0 | AA7: 0 | AB7: 57 | AC7: 5 | AD7: 0 | AE7: 0 | AF7: 0 | AG7: 1 | AH7: 1 | AI7: 0 | AJ7: 0 | AK7: 0 | AL7: 0x00000000
A8: 2 | B8: =IF(I8=0,"",VLOOKUP(J8,seriesName!A:B,2,TRUE)) -> 炎火装束・霸 | C8: 炎火装束【上衣】霸 | D8: 30 | E8: 6 | F8: =D8+VLOOKUP(E8,BuildupTable!L:O,4,FALSE) -> 30 | G8: 1 | H8: 0x0C200001 | I8: 1 | J8: 1 | K8: 8001 | L8: 30 | M8: 3 | N8: 4000 | O8: 12000 | P8: 2 | Q8: 1 | R8: 1 | S8: 2 | T8: 0 | U8: 0 | V8: 0 | W8: 0 | X8: 0 | Y8: 1 | Z8: 0 | AA8: 0 | AB8: 104 | AC8: 105 | AD8: 6 | AE8: 0 | AF8: 0 | AG8: 2 | AH8: 1 | AI8: 1 | AJ8: 0 | AK8: 0 | AL8: 0x00000000
A9: 3 | B9: =IF(I9=0,"",VLOOKUP(J9,seriesName!A:B,2,TRUE)) -> 炎火装束・霸 | C9: 炎火装束【手甲】霸 | D9: 30 | E9: 6 | F9: =D9+VLOOKUP(E9,BuildupTable!L:O,4,FALSE) -> 30 | G9: 1 | H9: 0x0C300001 | I9: 1 | J9: 1 | K9: 8001 | L9: 30 | M9: 3 | N9: 4000 | O9: 12000 | P9: 2 | Q9: 1 | R9: 1 | S9: 2 | T9: 0 | U9: 0 | V9: 0 | W9: 0 | X9: 0 | Y9: 0 | Z9: 1 | AA9: 0 | AB9: 6 | AC9: 91 | AD9: 0 | AE9: 0 | AF9: 0 | AG9: 2 | AH9: 1 | AI9: 0 | AJ9: 0 | AK9: 0 | AL9: 0x00000000
A10: 4 | B10: =IF(I10=0,"",VLOOKUP(J10,seriesName!A:B,2,TRUE)) -> 炎火装束・霸 | C10: 炎火装束【腰卷】霸 | D10: 30 | E10: 6 | F10: =D10+VLOOKUP(E10,BuildupTable!L:O,4,FALSE) -> 30 | G10: 1 | H10: 0x0C400001 | I10: 1 | J10: 1 | K10: 8001 | L10: 30 | M10: 3 | N10: 4000 | O10: 12000 | P10: 2 | Q10: 1 | R10: 1 | S10: 2 | T10: 0 | U10: 0 | V10: 0 | W10: 0 | X10: 0 | Y10: 2 | Z10: 0 | AA10: 0 | AB10: 104 | AC10: 6 | AD10: 0 | AE10: 0 | AF10: 0 | AG10: 1 | AH10: 1 | AI10: 0 | AJ10: 0 | AK10: 0 | AL10: 0x00000000
A11: 5 | B11: =IF(I11=0,"",VLOOKUP(J11,seriesName!A:B,2,TRUE)) -> 炎火装束・霸 | C11: 炎火装束【绑腿】霸 | D11: 30 | E11: 6 | F11: =D11+VLOOKUP(E11,BuildupTable!L:O,4,FALSE) -> 30 | G11: 1 | H11: 0x0C500001 | I11: 1 | J11: 1 | K11: 8001 | L11: 30 | M11: 3 | N11: 4000 | O11: 12000 | P11: 2 | Q11: 1 | R11: 1 | S11: 2 | T11: 0 | U11: 0 | V11: 0 | W11: 0 | X11: 0 | Y11: 1 | Z11: 0 | AA11: 0 | AB11: 105 | AC11: 5 | AD11: 0 | AE11: 0 | AF11: 0 | AG11: 2 | AH11: 1 | AI11: 0 | AJ11: 0 | AK11: 0 | AL11: 0x00000000
A12: 1 | B12: =IF(I12=0,"",VLOOKUP(J12,seriesName!A:B,2,TRUE)) -> 皮制 | C12: 皮制头饰 | D12: 1 | E12: 0 | F12: =D12+VLOOKUP(E12,BuildupTable!L:O,4,FALSE) -> 67 | G12: 2 | H12: 0x0C100002 | I12: 1 | J12: 2 | K12: 1002 | L12: 0 | M12: 0 | N12: 100 | O12: 300 | P12: 2 | Q12: 0 | R12: 0 | S12: 0 | T12: 0 | U12: 0 | V12: 0 | W12: 0 | X12: 0 | Y12: 0 | Z12: 0 | AA12: 0 | AB12: 96 | AC12: 0 | AD12: 0 | AE12: 0 | AF12: 0 | AG12: 1 | AH12: 0 | AI12: 0 | AJ12: 0 | AK12: 0 | AL12: 0x00000000
A13: 2 | B13: =IF(I13=0,"",VLOOKUP(J13,seriesName!A:B,2,TRUE)) -> 皮制 | C13: 皮制服饰 | D13: 1 | E13: 0 | F13: =D13+VLOOKUP(E13,BuildupTable!L:O,4,FALSE) -> 67 | G13: 2 | H13: 0x0C200002 | I13: 1 | J13: 2 | K13: 1002 | L13: 0 | M13: 0 | N13: 100 | O13: 300 | P13: 2 | Q13: 0 | R13: 0 | S13: 0 | T13: 0 | U13: 0 | V13: 0 | W13: 0 | X13: 0 | Y13: 0 | Z13: 0 | AA13: 0 | AB13: 79 | AC13: 0 | AD13: 0 | AE13: 0 | AF13: 0 | AG13: 1 | AH13: 0 | AI13: 0 | AJ13: 0 | AK13: 0 | AL13: 0x00000000
... A153: 2 | B153: =IF(I153=0,"",VLOOKUP(J153,seriesName!A:B,2,TRUE)) -> 混沌 | C153: 混沌的铠 | D153: 12 | E153: 2 | F153: =D153+VLOOKUP(E153,BuildupTable!L:O,4,FALSE) -> 64 | G153: 30 | H153: 0x0C20001E | I153: 1 | J153: 30 | K153: 3003 | L153: 69 | M153: 1 | N153: 500 | O153: 0 | P153: 2 | Q153: 0 | R153: 0 | S153: 2 | T153: -2 | U153: 0 | V153: 0 | W153: 0 | X153: 0 | Y153: 0 | Z153: 0 | AA153: 0 | AB153: 0 | AC153: 0 | AD153: 0 | AE153: 0 | AF153: 0 | AG153: 0 | AH153: 0 | AI153: 0 | AJ153: 0 | AK153: 0 | AL153: 0x00000000
A154: 3 | B154: =IF(I154=0,"",VLOOKUP(J154,seriesName!A:B,2,TRUE)) | C154: 0 | D154: 12 | E154: 2 | F154: =D154+VLOOKUP(E154,BuildupTable!L:O,4,FALSE) -> 64 | G154: 30 | H154: 0x0C30001E | I154: 0 | J154: 30 | K154: 3003 | L154: 69 | M154: 1 | N154: 500 | O154: 0 | P154: 2 | Q154: 0 | R154: 0 | S154: 2 | T154: -2 | U154: 0 | V154: 0 | W154: 0 | X154: 0 | Y154: 0 | Z154: 0 | AA154: 0 | AB154: 0 | AC154: 0 | AD154: 0 | AE154: 0 | AF154: 0 | AG154: 0 | AH154: 0 | AI154: 0 | AJ154: 0 | AK154: 0 | AL154: 0x00000000
A155: 4 | B155: =IF(I155=0,"",VLOOKUP(J155,seriesName!A:B,2,TRUE)) | C155: 0 | D155: 12 | E155: 2 | F155: =D155+VLOOKUP(E155,BuildupTable!L:O,4,FALSE) -> 64 | G155: 30 | H155: 0x0C40001E | I155: 0 | J155: 30 | K155: 3003 | L155: 69 | M155: 1 | N155: 500 | O155: 0 | P155: 2 | Q155: 0 | R155: 0 | S155: 2 | T155: -2 | U155: 0 | V155: 0 | W155: 0 | X155: 0 | Y155: 0 | Z155: 0 | AA155: 0 | AB155: 0 | AC155: 0 | AD155: 0 | AE155: 0 | AF155: 0 | AG155: 0 | AH155: 0 | AI155: 0 | AJ155: 0 | AK155: 0 | AL155: 0x00000000
A156: 5 | B156: =IF(I156=0,"",VLOOKUP(J156,seriesName!A:B,2,TRUE)) | C156: 0 | D156: 12 | E156: 2 | F156: =D156+VLOOKUP(E156,BuildupTable!L:O,4,FALSE) -> 64 | G156: 30 | H156: 0x0C50001E | I156: 0 | J156: 30 | K156: 3003 | L156: 69 | M156: 1 | N156: 500 | O156: 0 | P156: 2 | Q156: 0 | R156: 0 | S156: 2 | T156: -2 | U156: 0 | V156: 0 | W156: 0 | X156: 0 | Y156: 0 | Z156: 0 | AA156: 0 | AB156: 0 | AC156: 0 | AD156: 0 | AE156: 0 | AF156: 0 | AG156: 0 | AH156: 0 | AI156: 0 | AJ156: 0 | AK156: 0 | AL156: 0x00000000
A157: 1 | B157: =IF(I157=0,"",VLOOKUP(J157,seriesName!A:B,2,TRUE)) -> 混沌・霸 | C157: 混沌的包发・霸 | D157: 40 | E157: 7 | F157: =D157+VLOOKUP(E157,BuildupTable!L:O,4,FALSE) -> 46 | G157: 31 | H157: 0x0C10001F | I157: 1 | J157: 31 | K157: 9002 | L157: 69 | M157: 3 | N157: 4000 | O157: 0 | P157: 2 | Q157: 1 | R157: 1 | S157: 2 | T157: -2 | U157: 0 | V157: 0 | W157: 0 | X157: 0 | Y157: 2 | Z157: 0 | AA157: 0 | AB157: 87 | AC157: 0 | AD157: 0 | AE157: 0 | AF157: 0 | AG157: 1 | AH157: 0 | AI157: 0 | AJ157: 0 | AK157: 0 | AL157: 0x00000000
A158: 2 | B158: =IF(I158=0,"",VLOOKUP(J158,seriesName!A:B,2,TRUE)) -> 混沌・霸 | C158: 混沌的铠・霸 | D158: 40 | E158: 7 | F158: =D158+VLOOKUP(E158,BuildupTable!L:O,4,FALSE) -> 46 | G158: 31 | H158: 0x0C20001F | I158: 1 | J158: 31 | K158: 9002 | L158: 69 | M158: 3 | N158: 4000 | O158: 0 | P158: 2 | Q158: 1 | R158: 1 | S158: 2 | T158: -2 | U158: 0 | V158: 0 | W158: 0 | X158: 0 | Y158: 0 | Z158: 0 | AA158: 0 | AB158: 87 | AC158: 0 | AD158: 0 | AE158: 0 | AF158: 0 | AG158: 2 | AH158: 0 | AI158: 0 | AJ158: 0 | AK158: 0 | AL158: 0x00000000
A159: 3 | B159: =IF(I159=0,"",VLOOKUP(J159,seriesName!A:B,2,TRUE)) | C159: 0 | D159: 40 | E159: 7 | F159: =D159+VLOOKUP(E159,BuildupTable!L:O,4,FALSE) -> 46 | G159: 31 | H159: 0x0C30001F | I159: 0 | J159: 31 | K159: 9002 | L159: 69 | M159: 3 | N159: 4000 | O159: 0 | P159: 2 | Q159: 1 | R159: 1 | S159: 2 | T159: -2 | U159: 0 | V159: 0 | W159: 0 | X159: 0 | Y159: 0 | Z159: 0 | AA159: 0 | AB159: 0 | AC159: 0 | AD159: 0 | AE159: 0 | AF159: 0 | AG159: 0 | AH159: 0 | AI159: 0 | AJ159: 0 | AK159: 0 | AL159: 0x00000000
A160: 4 | B160: =IF(I160=0,"",VLOOKUP(J160,seriesName!A:B,2,TRUE)) | C160: 0 | D160: 40 | E160: 7 | F160: =D160+VLOOKUP(E160,BuildupTable!L:O,4,FALSE) -> 46 | G160: 31 | H160: 0x0C40001F | I160: 0 | J160: 31 | K160: 9002 | L160: 69 | M160: 3 | N160: 4000 | O160: 0 | P160: 2 | Q160: 1 | R160: 1 | S160: 2 | T160: -2 | U160: 0 | V160: 0 | W160: 0 | X160: 0 | Y160: 0 | Z160: 0 | AA160: 0 | AB160: 0 | AC160: 0 | AD160: 0 | AE160: 0 | AF160: 0 | AG160: 0 | AH160: 0 | AI160: 0 | AJ160: 0 | AK160: 0 | AL160: 0x00000000
A161: 5 | B161: =IF(I161=0,"",VLOOKUP(J161,seriesName!A:B,2,TRUE)) | C161: 0 | D161: 40 | E161: 7 | F161: =D161+VLOOKUP(E161,BuildupTable!L:O,4,FALSE) -> 46 | G161: 31 | H161: 0x0C50001F | I161: 0 | J161: 31 | K161: 9002 | L161: 69 | M161: 3 | N161: 4000 | O161: 0 | P161: 2 | Q161: 1 | R161: 1 | S161: 2 | T161: -2 | U161: 0 | V161: 0 | W161: 0 | X161: 0 | Y161: 0 | Z161: 0 | AA161: 0 | AB161: 0 | AC161: 0 | AD161: 0 | AE161: 0 | AF161: 0 | AG161: 0 | AH161: 0 | AI161: 0 | AJ161: 0 | AK161: 0 | AL161: 0x00000000
A162: 1 | B162: =IF(I162=0,"",VLOOKUP(J162,seriesName!A:B,2,TRUE)) -> 雪绒花 | C162: 雪绒花绽放 | D162: 12 | E162: 2 | F162: =D162+VLOOKUP(E162,BuildupTable!L:O,4,FALSE) -> 64 | G162: 32 | H162: 0x0C100020 | I162: 1 | J162: 32 | K162: 3004 | L162: 70 | M162: 1 | N162: 500 | O162: 0 | P162: 2 | Q162: 0 | R162: 0 | S162: -1 | T162: 3 | U162: 0 | V162: -1 | W162: 0 | X162: 0 | Y162: 0 | Z162: 0 | AA162: 0 | AB162: 73 | AC162: 0 | AD162: 0 | AE162: 0 | AF162: 0 | AG162: 1 | AH162: 0 | AI162: 0 | AJ162: 0 | AK162: 0 | AL162: 0x00000000
A163: 2 | B163: =IF(I163=0,"",VLOOKUP(J163,seriesName!A:B,2,TRUE)) -> 雪绒花 | C163: 雪绒花枝干 | D163: 12 | E163: 2 | F163: =D163+VLOOKUP(E163,BuildupTable!L:O,4,FALSE) -> 64 | G163: 32 | H163: 0x0C200020 | I163: 1 | J163: 32 | K163: 3004 | L163: 70 | M163: 1 | N163: 500 | O163: 0 | P163: 2 | Q163: 0 | R163: 0 | S163: -1 | T163: 3 | U163: 0 | V163: -1 | W163: 0 | X163: 0 | Y163: 0 | Z163: 0 | AA163: 0 | AB163: 58 | AC163: 0 | AD163: 0 | AE163: 0 | AF163: 0 | AG163: 1 | AH163: 0 | AI163: 0 | AJ163: 0 | AK163: 0 | AL163: 0x00000000
A164: 3 | B164: =IF(I164=0,"",VLOOKUP(J164,seriesName!A:B,2,TRUE)) -> 雪绒花 | C164: 雪绒花枝叶 | D164: 12 | E164: 2 | F164: =D164+VLOOKUP(E164,BuildupTable!L:O,4,FALSE) -> 64 | G164: 32 | H164: 0x0C300020 | I164: 1 | J164: 32 | K164: 3004 | L164: 70 | M164: 1 | N164: 500 | O164: 0 | P164: 2 | Q164: 0 | R164: 0 | S164: -1 | T164: 3 | U164: 0 | V164: -1 | W164: 0 | X164: 0 | Y164: 0 | Z164: 0 | AA164: 0 | AB164: 73 | AC164: 0 | AD164: 0 | AE164: 0 | AF164: 0 | AG164: 1 | AH164: 0 | AI164: 0 | AJ164: 0 | AK164: 0 | AL164: 0x00000000
A165: 4 | B165: =IF(I165=0,"",VLOOKUP(J165,seriesName!A:B,2,TRUE)) -> 雪绒花 | C165: 雪绒花叶片 | D165: 12 | E165: 2 | F165: =D165+VLOOKUP(E165,BuildupTable!L:O,4,FALSE) -> 64 | G165: 32 | H165: 0x0C400020 | I165: 1 | J165: 32 | K165: 3004 | L165: 70 | M165: 1 | N165: 500 | O165: 0 | P165: 2 | Q165: 0 | R165: 0 | S165: -1 | T165: 3 | U165: 0 | V165: -1 | W165: 0 | X165: 0 | Y165: 0 | Z165: 0 | AA165: 0 | AB165: 70 | AC165: 0 | AD165: 0 | AE165: 0 | AF165: 0 | AG165: 1 | AH165: 0 | AI165: 0 | AJ165: 0 | AK165: 0 | AL165: 0x00000000
A166: 5 | B166: =IF(I166=0,"",VLOOKUP(J166,seriesName!A:B,2,TRUE)) -> 雪绒花 | C166: 雪绒花扎根 | D166: 12 | E166: 2 | F166: =D166+VLOOKUP(E166,BuildupTable!L:O,4,FALSE) -> 64 | G166: 32 | H166: 0x0C500020 | I166: 1 | J166: 32 | K166: 3004 | L166: 70 | M166: 1 | N166: 500 | O166: 0 | P166: 2 | Q166: 0 | R166: 0 | S166: -1 | T166: 3 | U166: 0 | V166: -1 | W166: 0 | X166: 0 | Y166: 0 | Z166: 0 | AA166: 0 | AB166: 70 | AC166: 0 | AD166: 0 | AE166: 0 | AF166: 0 | AG166: 1 | AH166: 0 | AI166: 0 | AJ166: 0 | AK166: 0 | AL166: 0x00000000
A167: 1 | B167: =IF(I167=0,"",VLOOKUP(J167,seriesName!A:B,2,TRUE)) -> 雪绒花S | C167: 雪绒花S绽放 | D167: 40 | E167: 7 | F167: =D167+VLOOKUP(E167,BuildupTable!L:O,4,FALSE) -> 46 | G167: 33 | H167: 0x0C100021 | I167: 1 | J167: 33 | K167: 9003 | L167: 70 | M167: 3 | N167: 4000 | O167: 0 | P167: 2 | Q167: 1 | R167: 1 | S167: -1 | T167: 3 | U167: 0 | V167: -1 | W167: 0 | X167: 0 | Y167: 0 | Z167: 2 | AA167: 0 | AB167: 73 | AC167: 0 | AD167: 0 | AE167: 0 | AF167: 0 | AG167: 2 | AH167: 0 | AI167: 0 | AJ167: 0 | AK167: 0 | AL167: 0x00000000
A168: 2 | B168: =IF(I168=0,"",VLOOKUP(J168,seriesName!A:B,2,TRUE)) -> 雪绒花S | C168: 雪绒花S枝干 | D168: 40 | E168: 7 | F168: =D168+VLOOKUP(E168,BuildupTable!L:O,4,FALSE) -> 46 | G168: 33 | H168: 0x0C200021 | I168: 1 | J168: 33 | K168: 9003 | L168: 70 | M168: 3 | N168: 4000 | O168: 0 | P168: 2 | Q168: 1 | R168: 1 | S168: -1 | T168: 3 | U168: 0 | V168: -1 | W168: 0 | X168: 0 | Y168: 2 | Z168: 0 | AA168: 0 | AB168: 58 | AC168: 0 | AD168: 0 | AE168: 0 | AF168: 0 | AG168: 2 | AH168: 0 | AI168: 0 | AJ168: 0 | AK168: 0 | AL168: 0x00000000
A169: 3 | B169: =IF(I169=0,"",VLOOKUP(J169,seriesName!A:B,2,TRUE)) -> 雪绒花S | C169: 雪绒花S枝叶 | D169: 40 | E169: 7 | F169: =D169+VLOOKUP(E169,BuildupTable!L:O,4,FALSE) -> 46 | G169: 33 | H169: 0x0C300021 | I169: 1 | J169: 33 | K169: 9003 | L169: 70 | M169: 3 | N169: 4000 | O169: 0 | P169: 2 | Q169: 1 | R169: 1 | S169: -1 | T169: 3 | U169: 0 | V169: -1 | W169: 0 | X169: 0 | Y169: 0 | Z169: 0 | AA169: 0 | AB169: 82 | AC169: 0 | AD169: 0 | AE169: 0 | AF169: 0 | AG169: 1 | AH169: 0 | AI169: 0 | AJ169: 0 | AK169: 0 | AL169: 0x00000000
A170: 4 | B170: =IF(I170=0,"",VLOOKUP(J170,seriesName!A:B,2,TRUE)) -> 雪绒花S | C170: 雪绒花S叶片 | D170: 40 | E170: 7 | F170: =D170+VLOOKUP(E170,BuildupTable!L:O,4,FALSE) -> 46 | G170: 33 | H170: 0x0C400021 | I170: 1 | J170: 33 | K170: 9003 | L170: 70 | M170: 3 | N170: 4000 | O170: 0 | P170: 2 | Q170: 1 | R170: 1 | S170: -1 | T170: 3 | U170: 0 | V170: -1 | W170: 0 | X170: 0 | Y170: 0 | Z170: 1 | AA170: 0 | AB170: 58 | AC170: 0 | AD170: 0 | AE170: 0 | AF170: 0 | AG170: 1 | AH170: 0 | AI170: 0 | AJ170: 0 | AK170: 0 | AL170: 0x00000000
A171: 5 | B171: =IF(I171=0,"",VLOOKUP(J171,seriesName!A:B,2,TRUE)) -> 雪绒花S | C171: 雪绒花S扎根 | D171: 40 | E171: 7 | F171: =D171+VLOOKUP(E171,BuildupTable!L:O,4,FALSE) -> 46 | G171: 33 | H171: 0x0C500021 | I171: 1 | J171: 33 | K171: 9003 | L171: 70 | M171: 3 | N171: 4000 | O171: 0 | P171: 2 | Q171: 1 | R171: 1 | S171: -1 | T171: 3 | U171: 0 | V171: -1 | W171: 0 | X171: 0 | Y171: 1 | Z171: 0 | AA171: 1 | AB171: 73 | AC171: 0 | AD171: 0 | AE171: 0 | AF171: 0 | AG171: 1 | AH171: 0 | AI171: 0 | AJ171: 0 | AK171: 0 | AL171: 0x00000000
A172: 1 | B172: =IF(I172=0,"",VLOOKUP(J172,seriesName!A:B,2,TRUE)) -> 毒蝎 | C172: 毒蝎护头 | D172: 12 | E172: 2 | F172: =D172+VLOOKUP(E172,BuildupTable!L:O,4,FALSE) -> 64 | G172: 34 | H172: 0x0C100022 | I172: 1 | J172: 34 | K172: 3005 | L172: 71 | M172: 1 | N172: 500 | O172: 0 | P172: 2 | Q172: 0 | R172: 0 | S172: 3 | T172: -1 | U172: -1 | V172: -1 | W172: 3 | X172: 0 | Y172: 0 | Z172: 0 | AA172: 0 | AB172: 18 | AC172: 0 | AD172: 0 | AE172: 0 | AF172: 0 | AG172: 1 | AH172: 0 | AI172: 0 | AJ172: 0 | AK172: 0 | AL172: 0x00000000
A173: 2 | B173: =IF(I173=0,"",VLOOKUP(J173,seriesName!A:B,2,TRUE)) -> 毒蝎 | C173: 毒蝎上身 | D173: 12 | E173: 2 | F173: =D173+VLOOKUP(E173,BuildupTable!L:O,4,FALSE) -> 64 | G173: 34 | H173: 0x0C200022 | I173: 1 | J173: 34 | K173: 3005 | L173: 71 | M173: 1 | N173: 500 | O173: 0 | P173: 2 | Q173: 0 | R173: 0 | S173: 3 | T173: -1 | U173: -1 | V173: -1 | W173: 3 | X173: 0 | Y173: 0 | Z173: 0 | AA173: 0 | AB173: 6 | AC173: 0 | AD173: 0 | AE173: 0 | AF173: 0 | AG173: 1 | AH173: 0 | AI173: 0 | AJ173: 0 | AK173: 0 | AL173: 0x00000000
... A367: 1 | B367: =IF(I367=0,"",VLOOKUP(J367,seriesName!A:B,2,TRUE)) -> 丸鸟伪装 | C367: 丸鸟伪装 | D367: 14 | E367: 3 | F367: =D367+VLOOKUP(E367,BuildupTable!L:O,4,FALSE) -> 64 | G367: 73 | H367: 0x0C100049 | I367: 1 | J367: 71 | K367: 4007 | L367: 43 | M367: 1 | N367: 1000 | O367: 0 | P367: 2 | Q367: 0 | R367: 0 | S367: -3 | T367: -2 | U367: 1 | V367: -2 | W367: 0 | X367: 0 | Y367: 0 | Z367: 0 | AA367: 0 | AB367: 97 | AC367: 0 | AD367: 0 | AE367: 0 | AF367: 0 | AG367: 1 | AH367: 0 | AI367: 0 | AJ367: 0 | AK367: 0 | AL367: 0x00000000
A368: 2 | B368: =IF(I368=0,"",VLOOKUP(J368,seriesName!A:B,2,TRUE)) | C368: 0 | D368: 14 | E368: 3 | F368: =D368+VLOOKUP(E368,BuildupTable!L:O,4,FALSE) -> 64 | G368: 73 | H368: 0x0C200049 | I368: 0 | J368: 71 | K368: 4007 | L368: 43 | M368: 1 | N368: 1000 | O368: 0 | P368: 2 | Q368: 0 | R368: 0 | S368: -3 | T368: -2 | U368: 1 | V368: -2 | W368: 0 | X368: 0 | Y368: 0 | Z368: 0 | AA368: 0 | AB368: 0 | AC368: 0 | AD368: 0 | AE368: 0 | AF368: 0 | AG368: 0 | AH368: 0 | AI368: 0 | AJ368: 0 | AK368: 0 | AL368: 0x00000000
A369: 3 | B369: =IF(I369=0,"",VLOOKUP(J369,seriesName!A:B,2,TRUE)) | C369: 0 | D369: 14 | E369: 3 | F369: =D369+VLOOKUP(E369,BuildupTable!L:O,4,FALSE) -> 64 | G369: 73 | H369: 0x0C300049 | I369: 0 | J369: 71 | K369: 4007 | L369: 43 | M369: 1 | N369: 1000 | O369: 0 | P369: 2 | Q369: 0 | R369: 0 | S369: -3 | T369: -2 | U369: 1 | V369: -2 | W369: 0 | X369: 0 | Y369: 0 | Z369: 0 | AA369: 0 | AB369: 0 | AC369: 0 | AD369: 0 | AE369: 0 | AF369: 0 | AG369: 0 | AH369: 0 | AI369: 0 | AJ369: 0 | AK369: 0 | AL369: 0x00000000
A370: 4 | B370: =IF(I370=0,"",VLOOKUP(J370,seriesName!A:B,2,TRUE)) | C370: 0 | D370: 14 | E370: 3 | F370: =D370+VLOOKUP(E370,BuildupTable!L:O,4,FALSE) -> 64 | G370: 73 | H370: 0x0C400049 | I370: 0 | J370: 71 | K370: 4007 | L370: 43 | M370: 1 | N370: 1000 | O370: 0 | P370: 2 | Q370: 0 | R370: 0 | S370: -3 | T370: -2 | U370: 1 | V370: -2 | W370: 0 | X370: 0 | Y370: 0 | Z370: 0 | AA370: 0 | AB370: 0 | AC370: 0 | AD370: 0 | AE370: 0 | AF370: 0 | AG370: 0 | AH370: 0 | AI370: 0 | AJ370: 0 | AK370: 0 | AL370: 0x00000000
A371: 5 | B371: =IF(I371=0,"",VLOOKUP(J371,seriesName!A:B,2,TRUE)) | C371: 0 | D371: 14 | E371: 3 | F371: =D371+VLOOKUP(E371,BuildupTable!L:O,4,FALSE) -> 64 | G371: 73 | H371: 0x0C500049 | I371: 0 | J371: 71 | K371: 4007 | L371: 43 | M371: 1 | N371: 1000 | O371: 0 | P371: 2 | Q371: 0 | R371: 0 | S371: -3 | T371: -2 | U371: 1 | V371: -2 | W371: 0 | X371: 0 | Y371: 0 | Z371: 0 | AA371: 0 | AB371: 0 | AC371: 0 | AD371: 0 | AE371: 0 | AF371: 0 | AG371: 0 | AH371: 0 | AI371: 0 | AJ371: 0 | AK371: 0 | AL371: 0x00000000
A372: 1 | B372: =IF(I372=0,"",VLOOKUP(J372,seriesName!A:B,2,TRUE)) -> 丸鸟S伪装 | C372: 丸鸟S伪装 | D372: 54 | E372: 11 | F372: =D372+VLOOKUP(E372,BuildupTable!L:O,4,FALSE) -> 74 | G372: 74 | H372: 0x0C10004A | I372: 1 | J372: 72 | K372: 11006 | L372: 43 | M372: 5 | N372: 9000 | O372: 0 | P372: 2 | Q372: 1 | R372: 1 | S372: -3 | T372: -2 | U372: 1 | V372: -2 | W372: 0 | X372: 0 | Y372: 0 | Z372: 0 | AA372: 0 | AB372: 97 | AC372: 84 | AD372: 0 | AE372: 0 | AF372: 0 | AG372: 1 | AH372: 1 | AI372: 0 | AJ372: 0 | AK372: 0 | AL372: 0x00000000
...

Sheet armorBaseData(sheet)
B1: lookup_Series | C1: lookup_Armor | D1: 模型 | E1: maxDef | F1: Lv1SlotNum | G1: Lv2SlotNum | H1: Lv3SlotNum | I1: Lv4SlotNum | J1: SkillLookUp[0] | K1: SkillLV[0] | L1: SkillLookUp[1] | M1: SkillLV[1] | N1: SkillLookUp[2] | O1: SkillLV[2] | P1: SkillLookUp[3] | Q1: SkillLV[3] | R1: SkillLookUp[4] | S1: SkillLV[4] | T1: 词条池 | U1: Cost | V1: parseArmorId | W1: Id | X1: IsValid | Y1: Series | Z1: SortId | AA1: ModelId | AB1: Rare | AC1: Value | AD1: BuyValue | AE1: SexualEquipable | AF1: SymbolColor1 | AG1: SymbolColor2 | AH1: DefVal | AI1: FireRegVal | AJ1: WaterRegVal | AK1: IceRegVal | AL1: ThunderRegVal | AM1: DragonRegVal | AN1: BuildupTable | AO1: BuffFormula | AP1: DecorationsNumList[0] | AQ1: DecorationsNumList[1] | AR1: DecorationsNumList[2] | AS1: DecorationsNumList[3] | AT1: SkillList[0] | AU1: SkillList[1] | AV1: SkillList[2] | AW1: SkillList[3] | AX1: SkillList[4] | AY1: SkillLvList[0] | AZ1: SkillLvList[1] | BA1: SkillLvList[2] | BB1: SkillLvList[3] | BC1: SkillLvList[4] | BD1: IdAfterExChange | BE1: CustomTableNo | BF1: CustomCost | BG1: parseArmorIdHex
A2: =IF(X2=0,0,HEX2DEC(MID(W2,5,1))) -> 1 | B2: =IF(X2=0,"",VLOOKUP(Y2,seriesName!A:B,2,TRUE)) -> 炎火装束 | C2: =IF(A2=1,VLOOKUP(V2,Head!A:B,2,TRUE),IF(A2=2,VLOOKUP(V2,Chest!A:B,2,TRUE),IF(A2=3,VLOOKUP(V2,Arm!A:B,2,TRUE),IF(A2=4,VLOOKUP(V2,Waist!A:B,2,TRUE),IF(A2=5,VLOOKUP(V2,Leg!A:B,2,TRUE),""))))) -> 炎火装束【头巾】 | D2: =IF(X2=1,VLOOKUP(AA2,modelID!A:B,2,FALSE),"") -> pl200 | E2: =IF(X2=0,"",AH2+VLOOKUP(AN2,BuildupTable!L:O,4,FALSE)) -> 67 | F2: =AP2 -> 0 | G2: =AQ2 -> 0 | H2: =AR2 -> 0 | I2: =AS2 -> 0 | J2: =IF(AT2=0,"",VLOOKUP(AT2,skillbasedata!A:B,2,TRUE)) -> 精灵加护 | K2: =AY2 -> 1 | L2: =IF(AU2=0,"",VLOOKUP(AU2,skillbasedata!A:B,2,TRUE)) | M2: =AZ2 -> 0 | N2: =IF(AV2=0,"",VLOOKUP(AV2,skillbasedata!A:B,2,TRUE)) | O2: =BA2 -> 0 | P2: =IF(AW2=0,"",VLOOKUP(AW2,skillbasedata!A:B,2,TRUE)) | Q2: =BB2 -> 0 | R2: =IF(AX2=0,"",VLOOKUP(AX2,skillbasedata!A:B,2,TRUE)) | S2: =BC2 -> 0 | T2: =BE2 -> 0 | U2: =BF2 -> 0 | V2: =IF(BG2=0,0,HEX2DEC(BG2)) -> 0 | W2: 0x0C100000 | X2: 1 | Y2: 0 | Z2: 1001 | AA2: 30 | AB2: 0 | AC2: 100 | AD2: 300 | AE2: 2 | AF2: 0 | AG2: 0 | AH2: 1 | AI2: 1 | AJ2: 0 | AK2: 0 | AL2: 0 | AM2: 0 | AN2: 0 | AO2: 0 | AP2: 0 | AQ2: 0 | AR2: 0 | AS2: 0 | AT2: 57 | AU2: 0 | AV2: 0 | AW2: 0 | AX2: 0 | AY2: 1 | AZ2: 0 | BA2: 0 | BB2: 0 | BC2: 0 | BD2: 0x00000000 | BE2: 0 | BF2: 0 | BG2: =MID(W2,7,4) -> 0000
A3: =IF(X3=0,0,HEX2DEC(MID(W3,5,1))) -> 2 | B3: =IF(X3=0,"",VLOOKUP(Y3,seriesName!A:B,2,TRUE)) -> 炎火装束 | C3: =IF(A3=1,VLOOKUP(V3,Head!A:B,2,TRUE),IF(A3=2,VLOOKUP(V3,Chest!A:B,2,TRUE),IF(A3=3,VLOOKUP(V3,Arm!A:B,2,TRUE),IF(A3=4,VLOOKUP(V3,Waist!A:B,2,TRUE),IF(A3=5,VLOOKUP(V3,Leg!A:B,2,TRUE),""))))) -> 炎火装束【上衣】 | D3: =IF(X3=1,VLOOKUP(AA3,modelID!A:B,2,FALSE),"") -> pl200 | E3: =IF(X3=0,"",AH3+VLOOKUP(AN3,BuildupTable!L:O,4,FALSE)) -> 67 | F3: =AP3 -> 0 | G3: =AQ3 -> 0 | H3: =AR3 -> 0 | I3: =AS3 -> 0 | J3: =IF(AT3=0,"",VLOOKUP(AT3,skillbasedata!A:B,2,TRUE)) -> 翔虫使 | K3: =AY3 -> 1 | L3: =IF(AU3=0,"",VLOOKUP(AU3,skillbasedata!A:B,2,TRUE)) | M3: =AZ3 -> 0 | N3: =IF(AV3=0,"",VLOOKUP(AV3,skillbasedata!A:B,2,TRUE)) | O3: =BA3 -> 0 | P3: =IF(AW3=0,"",VLOOKUP(AW3,skillbasedata!A:B,2,TRUE)) | Q3: =BB3 -> 0 | R3: =IF(AX3=0,"",VLOOKUP(AX3,skillbasedata!A:B,2,TRUE)) | S3: =BC3 -> 0 | T3: =BE3 -> 0 | U3: =BF3 -> 0 | V3: =IF(BG3=0,0,HEX2DEC(BG3)) -> 0 | W3: 0x0C200000 | X3: 1 | Y3: 0 | Z3: 1001 | AA3: 30 | AB3: 0 | AC3: 100 | AD3: 300 | AE3: 2 | AF3: 0 | AG3: 0 | AH3: 1 | AI3: 1 | AJ3: 0 | AK3: 0 | AL3: 0 | AM3: 0 | AN3: 0 | AO3: 0 | AP3: 0 | AQ3: 0 | AR3: 0 | AS3: 0 | AT3: 104 | AU3: 0 | AV3: 0 | AW3: 0 | AX3: 0 | AY3: 1 | AZ3: 0 | BA3: 0 | BB3: 0 | BC3: 0 | BD3: 0x00000000 | BE3: 0 | BF3: 0 | BG3: =MID(W3,7,4) -> 0000
A4: =IF(X4=0,0,HEX2DEC(MID(W4,5,1))) -> 3 | B4: =IF(X4=0,"",VLOOKUP(Y4,seriesName!A:B,2,TRUE)) -> 炎火装束 | C4: =IF(A4=1,VLOOKUP(V4,Head!A:B,2,TRUE),IF(A4=2,VLOOKUP(V4,Chest!A:B,2,TRUE),IF(A4=3,VLOOKUP(V4,Arm!A:B,2,TRUE),IF(A4=4,VLOOKUP(V4,Waist!A:B,2,TRUE),IF(A4=5,VLOOKUP(V4,Leg!A:B,2,TRUE),""))))) -> 炎火装束【手甲】 | D4: =IF(X4=1,VLOOKUP(AA4,modelID!A:B,2,FALSE),"") -> pl200 | E4: =IF(X4=0,"",AH4+VLOOKUP(AN4,BuildupTable!L:O,4,FALSE)) -> 67 | F4: =AP4 -> 0 | G4: =AQ4 -> 0 | H4: =AR4 -> 0 | I4: =AS4 -> 0 | J4: =IF(AT4=0,"",VLOOKUP(AT4,skillbasedata!A:B,2,TRUE)) -> 火场怪力 | K4: =AY4 -> 1 | L4: =IF(AU4=0,"",VLOOKUP(AU4,skillbasedata!A:B,2,TRUE)) | M4: =AZ4 -> 0 | N4: =IF(AV4=0,"",VLOOKUP(AV4,skillbasedata!A:B,2,TRUE)) | O4: =BA4 -> 0 | P4: =IF(AW4=0,"",VLOOKUP(AW4,skillbasedata!A:B,2,TRUE)) | Q4: =BB4 -> 0 | R4: =IF(AX4=0,"",VLOOKUP(AX4,skillbasedata!A:B,2,TRUE)) | S4: =BC4 -> 0 | T4: =BE4 -> 0 | U4: =BF4 -> 0 | V4: =IF(BG4=0,0,HEX2DEC(BG4)) -> 0 | W4: 0x0C300000 | X4: 1 | Y4: 0 | Z4: 1001 | AA4: 30 | AB4: 0 | AC4: 100 | AD4: 300 | AE4: 2 | AF4: 0 | AG4: 0 | AH4: 1 | AI4: 1 | AJ4: 0 | AK4: 0 | AL4: 0 | AM4: 0 | AN4: 0 | AO4: 0 | AP4: 0 | AQ4: 0 | AR4: 0 | AS4: 0 | AT4: 91 | AU4: 0 | AV4: 0 | AW4: 0 | AX4: 0 | AY4: 1 | AZ4: 0 | BA4: 0 | BB4: 0 | BC4: 0 | BD4: 0x00000000 | BE4: 0 | BF4: 0 | BG4: =MID(W4,7,4) -> 0000
A5: =IF(X5=0,0,HEX2DEC(MID(W5,5,1))) -> 4 | B5: =IF(X5=0,"",VLOOKUP(Y5,seriesName!A:B,2,TRUE)) -> 炎火装束 | C5: =IF(A5=1,VLOOKUP(V5,Head!A:B,2,TRUE),IF(A5=2,VLOOKUP(V5,Chest!A:B,2,TRUE),IF(A5=3,VLOOKUP(V5,Arm!A:B,2,TRUE),IF(A5=4,VLOOKUP(V5,Waist!A:B,2,TRUE),IF(A5=5,VLOOKUP(V5,Leg!A:B,2,TRUE),""))))) -> 炎火装束【腰卷】 | D5: =IF(X5=1,VLOOKUP(AA5,modelID!A:B,2,FALSE),"") -> pl200 | E5: =IF(X5=0,"",AH5+VLOOKUP(AN5,BuildupTable!L:O,4,FALSE)) -> 67 | F5: =AP5 -> 0 | G5: =AQ5 -> 0 | H5: =AR5 -> 0 | I5: =AS5 -> 0 | J5: =IF(AT5=0,"",VLOOKUP(AT5,skillbasedata!A:B,2,TRUE)) -> 看破 | K5: =AY5 -> 1 | L5: =IF(AU5=0,"",VLOOKUP(AU5,skillbasedata!A:B,2,TRUE)) | M5: =AZ5 -> 0 | N5: =IF(AV5=0,"",VLOOKUP(AV5,skillbasedata!A:B,2,TRUE)) | O5: =BA5 -> 0 | P5: =IF(AW5=0,"",VLOOKUP(AW5,skillbasedata!A:B,2,TRUE)) | Q5: =BB5 -> 0 | R5: =IF(AX5=0,"",VLOOKUP(AX5,skillbasedata!A:B,2,TRUE)) | S5: =BC5 -> 0 | T5: =BE5 -> 0 | U5: =BF5 -> 0 | V5: =IF(BG5=0,0,HEX2DEC(BG5)) -> 0 | W5: 0x0C400000 | X5: 1 | Y5: 0 | Z5: 1001 | AA5: 30 | AB5: 0 | AC5: 100 | AD5: 300 | AE5: 2 | AF5: 0 | AG5: 0 | AH5: 1 | AI5: 1 | AJ5: 0 | AK5: 0 | AL5: 0 | AM5: 0 | AN5: 0 | AO5: 0 | AP5: 0 | AQ5: 0 | AR5: 0 | AS5: 0 | AT5: 6 | AU5: 0 | AV5: 0 | AW5: 0 | AX5: 0 | AY5: 1 | AZ5: 0 | BA5: 0 | BB5: 0 | BC5: 0 | BD5: 0x00000000 | BE5: 0 | BF5: 0 | BG5: =MID(W5,7,4) -> 0000
A6: =IF(X6=0,0,HEX2DEC(MID(W6,5,1))) -> 5 | B6: =IF(X6=0,"",VLOOKUP(Y6,seriesName!A:B,2,TRUE)) -> 炎火装束 | C6: =IF(A6=1,VLOOKUP(V6,Head!A:B,2,TRUE),IF(A6=2,VLOOKUP(V6,Chest!A:B,2,TRUE),IF(A6=3,VLOOKUP(V6,Arm!A:B,2,TRUE),IF(A6=4,VLOOKUP(V6,Waist!A:B,2,TRUE),IF(A6=5,VLOOKUP(V6,Leg!A:B,2,TRUE),""))))) -> 炎火装束【绑腿】 | D6: =IF(X6=1,VLOOKUP(AA6,modelID!A:B,2,FALSE),"") -> pl200 | E6: =IF(X6=0,"",AH6+VLOOKUP(AN6,BuildupTable!L:O,4,FALSE)) -> 67 | F6: =AP6 -> 0 | G6: =AQ6 -> 0 | H6: =AR6 -> 0 | I6: =AS6 -> 0 | J6: =IF(AT6=0,"",VLOOKUP(AT6,skillbasedata!A:B,2,TRUE)) -> 墙面移动 | K6: =AY6 -> 1 | L6: =IF(AU6=0,"",VLOOKUP(AU6,skillbasedata!A:B,2,TRUE)) | M6: =AZ6 -> 0 | N6: =IF(AV6=0,"",VLOOKUP(AV6,skillbasedata!A:B,2,TRUE)) | O6: =BA6 -> 0 | P6: =IF(AW6=0,"",VLOOKUP(AW6,skillbasedata!A:B,2,TRUE)) | Q6: =BB6 -> 0 | R6: =IF(AX6=0,"",VLOOKUP(AX6,skillbasedata!A:B,2,TRUE)) | S6: =BC6 -> 0 | T6: =BE6 -> 0 | U6: =BF6 -> 0 | V6: =IF(BG6=0,0,HEX2DEC(BG6)) -> 0 | W6: 0x0C500000 | X6: 1 | Y6: 0 | Z6: 1001 | AA6: 30 | AB6: 0 | AC6: 100 | AD6: 300 | AE6: 2 | AF6: 0 | AG6: 0 | AH6: 1 | AI6: 1 | AJ6: 0 | AK6: 0 | AL6: 0 | AM6: 0 | AN6: 0 | AO6: 0 | AP6: 0 | AQ6: 0 | AR6: 0 | AS6: 0 | AT6: 105 | AU6: 0 | AV6: 0 | AW6: 0 | AX6: 0 | AY6: 1 | AZ6: 0 | BA6: 0 | BB6: 0 | BC6: 0 | BD6: 0x00000000 | BE6: 0 | BF6: 0 | BG6: =MID(W6,7,4) -> 0000
A7: =IF(X7=0,0,HEX2DEC(MID(W7,5,1))) -> 1 | B7: =IF(X7=0,"",VLOOKUP(Y7,seriesName!A:B,2,TRUE)) -> 炎火装束・霸 | C7: =IF(A7=1,VLOOKUP(V7,Head!A:B,2,TRUE),IF(A7=2,VLOOKUP(V7,Chest!A:B,2,TRUE),IF(A7=3,VLOOKUP(V7,Arm!A:B,2,TRUE),IF(A7=4,VLOOKUP(V7,Waist!A:B,2,TRUE),IF(A7=5,VLOOKUP(V7,Leg!A:B,2,TRUE),""))))) -> 炎火装束【头巾】霸 | D7: =IF(X7=1,VLOOKUP(AA7,modelID!A:B,2,FALSE),"") -> pl200 | E7: =IF(X7=0,"",AH7+VLOOKUP(AN7,BuildupTable!L:O,4,FALSE)) -> 68 | F7: =AP7 -> 1 | G7: =AQ7 -> 0 | H7: =AR7 -> 0 | I7: =AS7 -> 0 | J7: =IF(AT7=0,"",VLOOKUP(AT7,skillbasedata!A:B,2,TRUE)) -> 精灵加护 | K7: =AY7 -> 1 | L7: =IF(AU7=0,"",VLOOKUP(AU7,skillbasedata!A:B,2,TRUE)) -> 死里逃生 | M7: =AZ7 -> 1 | N7: =IF(AV7=0,"",VLOOKUP(AV7,skillbasedata!A:B,2,TRUE)) | O7: =BA7 -> 0 | P7: =IF(AW7=0,"",VLOOKUP(AW7,skillbasedata!A:B,2,TRUE)) | Q7: =BB7 -> 0 | R7: =IF(AX7=0,"",VLOOKUP(AX7,skillbasedata!A:B,2,TRUE)) | S7: =BC7 -> 0 | T7: =BE7 -> 0 | U7: =BF7 -> 0 | V7: =IF(BG7=0,0,HEX2DEC(BG7)) -> 1 | W7: 0x0C100001 | X7: 1 | Y7: 1 | Z7: 8001 | AA7: 30 | AB7: 3 | AC7: 4000 | AD7: 12000 | AE7: 2 | AF7: 1 | AG7: 1 | AH7: 30 | AI7: 2 | AJ7: 0 | AK7: 0 | AL7: 0 | AM7: 0 | AN7: 8 | AO7: 0 | AP7: 1 | AQ7: 0 | AR7: 0 | AS7: 0 | AT7: 57 | AU7: 5 | AV7: 0 | AW7: 0 | AX7: 0 | AY7: 1 | AZ7: 1 | BA7: 0 | BB7: 0 | BC7: 0 | BD7: 0x00000000 | BE7: 0 | BF7: 0 | BG7: =MID(W7,7,4) -> 0001
A8: =IF(X8=0,0,HEX2DEC(MID(W8,5,1))) -> 2 | B8: =IF(X8=0,"",VLOOKUP(Y8,seriesName!A:B,2,TRUE)) -> 炎火装束・霸 | C8: =IF(A8=1,VLOOKUP(V8,Head!A:B,2,TRUE),IF(A8=2,VLOOKUP(V8,Chest!A:B,2,TRUE),IF(A8=3,VLOOKUP(V8,Arm!A:B,2,TRUE),IF(A8=4,VLOOKUP(V8,Waist!A:B,2,TRUE),IF(A8=5,VLOOKUP(V8,Leg!A:B,2,TRUE),""))))) -> 炎火装束【上衣】霸 | D8: =IF(X8=1,VLOOKUP(AA8,modelID!A:B,2,FALSE),"") -> pl200 | E8: =IF(X8=0,"",AH8+VLOOKUP(AN8,BuildupTable!L:O,4,FALSE)) -> 68 | F8: =AP8 -> 1 | G8: =AQ8 -> 0 | H8: =AR8 -> 0 | I8: =AS8 -> 0 | J8: =IF(AT8=0,"",VLOOKUP(AT8,skillbasedata!A:B,2,TRUE)) -> 翔虫使 | K8: =AY8 -> 2 | L8: =IF(AU8=0,"",VLOOKUP(AU8,skillbasedata!A:B,2,TRUE)) -> 墙面移动 | M8: =AZ8 -> 1 | N8: =IF(AV8=0,"",VLOOKUP(AV8,skillbasedata!A:B,2,TRUE)) -> 看破 | O8: =BA8 -> 1 | P8: =IF(AW8=0,"",VLOOKUP(AW8,skillbasedata!A:B,2,TRUE)) | Q8: =BB8 -> 0 | R8: =IF(AX8=0,"",VLOOKUP(AX8,skillbasedata!A:B,2,TRUE)) | S8: =BC8 -> 0 | T8: =BE8 -> 0 | U8: =BF8 -> 0 | V8: =IF(BG8=0,0,HEX2DEC(BG8)) -> 1 | W8: 0x0C200001 | X8: 1 | Y8: 1 | Z8: 8001 | AA8: 30 | AB8: 3 | AC8: 4000 | AD8: 12000 | AE8: 2 | AF8: 1 | AG8: 1 | AH8: 30 | AI8: 2 | AJ8: 0 | AK8: 0 | AL8: 0 | AM8: 0 | AN8: 8 | AO8: 0 | AP8: 1 | AQ8: 0 | AR8: 0 | AS8: 0 | AT8: 104 | AU8: 105 | AV8: 6 | AW8: 0 | AX8: 0 | AY8: 2 | AZ8: 1 | BA8: 1 | BB8: 0 | BC8: 0 | BD8: 0x00000000 | BE8: 0 | BF8: 0 | BG8: =MID(W8,7,4) -> 0001
A9: =IF(X9=0,0,HEX2DEC(MID(W9,5,1))) -> 3 | B9: =IF(X9=0,"",VLOOKUP(Y9,seriesName!A:B,2,TRUE)) -> 炎火装束・霸 | C9: =IF(A9=1,VLOOKUP(V9,Head!A:B,2,TRUE),IF(A9=2,VLOOKUP(V9,Chest!A:B,2,TRUE),IF(A9=3,VLOOKUP(V9,Arm!A:B,2,TRUE),IF(A9=4,VLOOKUP(V9,Waist!A:B,2,TRUE),IF(A9=5,VLOOKUP(V9,Leg!A:B,2,TRUE),""))))) -> 炎火装束【手甲】霸 | D9: =IF(X9=1,VLOOKUP(AA9,modelID!A:B,2,FALSE),"") -> pl200 | E9: =IF(X9=0,"",AH9+VLOOKUP(AN9,BuildupTable!L:O,4,FALSE)) -> 68 | F9: =AP9 -> 0 | G9: =AQ9 -> 1 | H9: =AR9 -> 0 | I9: =AS9 -> 0 | J9: =IF(AT9=0,"",VLOOKUP(AT9,skillbasedata!A:B,2,TRUE)) -> 看破 | K9: =AY9 -> 2 | L9: =IF(AU9=0,"",VLOOKUP(AU9,skillbasedata!A:B,2,TRUE)) -> 火场怪力 | M9: =AZ9 -> 1 | N9: =IF(AV9=0,"",VLOOKUP(AV9,skillbasedata!A:B,2,TRUE)) | O9: =BA9 -> 0 | P9: =IF(AW9=0,"",VLOOKUP(AW9,skillbasedata!A:B,2,TRUE)) | Q9: =BB9 -> 0 | R9: =IF(AX9=0,"",VLOOKUP(AX9,skillbasedata!A:B,2,TRUE)) | S9: =BC9 -> 0 | T9: =BE9 -> 0 | U9: =BF9 -> 0 | V9: =IF(BG9=0,0,HEX2DEC(BG9)) -> 1 | W9: 0x0C300001 | X9: 1 | Y9: 1 | Z9: 8001 | AA9: 30 | AB9: 3 | AC9: 4000 | AD9: 12000 | AE9: 2 | AF9: 1 | AG9: 1 | AH9: 30 | AI9: 2 | AJ9: 0 | AK9: 0 | AL9: 0 | AM9: 0 | AN9: 8 | AO9: 0 | AP9: 0 | AQ9: 1 | AR9: 0 | AS9: 0 | AT9: 6 | AU9: 91 | AV9: 0 | AW9: 0 | AX9: 0 | AY9: 2 | AZ9: 1 | BA9: 0 | BB9: 0 | BC9: 0 | BD9: 0x00000000 | BE9: 0 | BF9: 0 | BG9: =MID(W9,7,4) -> 0001
A10: =IF(X10=0,0,HEX2DEC(MID(W10,5,1))) -> 4 | B10: =IF(X10=0,"",VLOOKUP(Y10,seriesName!A:B,2,TRUE)) -> 炎火装束・霸 | C10: =IF(A10=1,VLOOKUP(V10,Head!A:B,2,TRUE),IF(A10=2,VLOOKUP(V10,Chest!A:B,2,TRUE),IF(A10=3,VLOOKUP(V10,Arm!A:B,2,TRUE),IF(A10=4,VLOOKUP(V10,Waist!A:B,2,TRUE),IF(A10=5,VLOOKUP(V10,Leg!A:B,2,TRUE),""))))) -> 炎火装束【腰卷】霸 | D10: =IF(X10=1,VLOOKUP(AA10,modelID!A:B,2,FALSE),"") -> pl200 | E10: =IF(X10=0,"",AH10+VLOOKUP(AN10,BuildupTable!L:O,4,FALSE)) -> 68 | F10: =AP10 -> 2 | G10: =AQ10 -> 0 | H10: =AR10 -> 0 | I10: =AS10 -> 0 | J10: =IF(AT10=0,"",VLOOKUP(AT10,skillbasedata!A:B,2,TRUE)) -> 翔虫使 | K10: =AY10 -> 1 | L10: =IF(AU10=0,"",VLOOKUP(AU10,skillbasedata!A:B,2,TRUE)) -> 看破 | M10: =AZ10 -> 1 | N10: =IF(AV10=0,"",VLOOKUP(AV10,skillbasedata!A:B,2,TRUE)) | O10: =BA10 -> 0 | P10: =IF(AW10=0,"",VLOOKUP(AW10,skillbasedata!A:B,2,TRUE)) | Q10: =BB10 -> 0 | R10: =IF(AX10=0,"",VLOOKUP(AX10,skillbasedata!A:B,2,TRUE)) | S10: =BC10 -> 0 | T10: =BE10 -> 0 | U10: =BF10 -> 0 | V10: =IF(BG10=0,0,HEX2DEC(BG10)) -> 1 | W10: 0x0C400001 | X10: 1 | Y10: 1 | Z10: 8001 | AA10: 30 | AB10: 3 | AC10: 4000 | AD10: 12000 | AE10: 2 | AF10: 1 | AG10: 1 | AH10: 30 | AI10: 2 | AJ10: 0 | AK10: 0 | AL10: 0 | AM10: 0 | AN10: 8 | AO10: 0 | AP10: 2 | AQ10: 0 | AR10: 0 | AS10: 0 | AT10: 104 | AU10: 6 | AV10: 0 | AW10: 0 | AX10: 0 | AY10: 1 | AZ10: 1 | BA10: 0 | BB10: 0 | BC10: 0 | BD10: 0x00000000 | BE10: 0 | BF10: 0 | BG10: =MID(W10,7,4) -> 0001
A11: =IF(X11=0,0,HEX2DEC(MID(W11,5,1))) -> 5 | B11: =IF(X11=0,"",VLOOKUP(Y11,seriesName!A:B,2,TRUE)) -> 炎火装束・霸 | C11: =IF(A11=1,VLOOKUP(V11,Head!A:B,2,TRUE),IF(A11=2,VLOOKUP(V11,Chest!A:B,2,TRUE),IF(A11=3,VLOOKUP(V11,Arm!A:B,2,TRUE),IF(A11=4,VLOOKUP(V11,Waist!A:B,2,TRUE),IF(A11=5,VLOOKUP(V11,Leg!A:B,2,TRUE),""))))) -> 炎火装束【绑腿】霸 | D11: =IF(X11=1,VLOOKUP(AA11,modelID!A:B,2,FALSE),"") -> pl200 | E11: =IF(X11=0,"",AH11+VLOOKUP(AN11,BuildupTable!L:O,4,FALSE)) -> 68 | F11: =AP11 -> 1 | G11: =AQ11 -> 0 | H11: =AR11 -> 0 | I11: =AS11 -> 0 | J11: =IF(AT11=0,"",VLOOKUP(AT11,skillbasedata!A:B,2,TRUE)) -> 墙面移动 | K11: =AY11 -> 2 | L11: =IF(AU11=0,"",VLOOKUP(AU11,skillbasedata!A:B,2,TRUE)) -> 死里逃生 | M11: =AZ11 -> 1 | N11: =IF(AV11=0,"",VLOOKUP(AV11,skillbasedata!A:B,2,TRUE)) | O11: =BA11 -> 0 | P11: =IF(AW11=0,"",VLOOKUP(AW11,skillbasedata!A:B,2,TRUE)) | Q11: =BB11 -> 0 | R11: =IF(AX11=0,"",VLOOKUP(AX11,skillbasedata!A:B,2,TRUE)) | S11: =BC11 -> 0 | T11: =BE11 -> 0 | U11: =BF11 -> 0 | V11: =IF(BG11=0,0,HEX2DEC(BG11)) -> 1 | W11: 0x0C500001 | X11: 1 | Y11: 1 | Z11: 8001 | AA11: 30 | AB11: 3 | AC11: 4000 | AD11: 12000 | AE11: 2 | AF11: 1 | AG11: 1 | AH11: 30 | AI11: 2 | AJ11: 0 | AK11: 0 | AL11: 0 | AM11: 0 | AN11: 8 | AO11: 0 | AP11: 1 | AQ11: 0 | AR11: 0 | AS11: 0 | AT11: 105 | AU11: 5 | AV11: 0 | AW11: 0 | AX11: 0 | AY11: 2 | AZ11: 1 | BA11: 0 | BB11: 0 | BC11: 0 | BD11: 0x00000000 | BE11: 0 | BF11: 0 | BG11: =MID(W11,7,4) -> 0001
A12: =IF(X12=0,0,HEX2DEC(MID(W12,5,1))) -> 1 | B12: =IF(X12=0,"",VLOOKUP(Y12,seriesName!A:B,2,TRUE)) -> 皮制 | C12: =IF(A12=1,VLOOKUP(V12,Head!A:B,2,TRUE),IF(A12=2,VLOOKUP(V12,Chest!A:B,2,TRUE),IF(A12=3,VLOOKUP(V12,Arm!A:B,2,TRUE),IF(A12=4,VLOOKUP(V12,Waist!A:B,2,TRUE),IF(A12=5,VLOOKUP(V12,Leg!A:B,2,TRUE),""))))) -> 皮制头饰 | D12: =IF(X12=1,VLOOKUP(AA12,modelID!A:B,2,FALSE),"") -> pl001 | E12: =IF(X12=0,"",AH12+VLOOKUP(AN12,BuildupTable!L:O,4,FALSE)) -> 67 | F12: =AP12 -> 0 | G12: =AQ12 -> 0 | H12: =AR12 -> 0 | I12: =AS12 -> 0 | J12: =IF(AT12=0,"",VLOOKUP(AT12,skillbasedata!A:B,2,TRUE)) -> 饥饿耐性 | K12: =AY12 -> 1 | L12: =IF(AU12=0,"",VLOOKUP(AU12,skillbasedata!A:B,2,TRUE)) | M12: =AZ12 -> 0 | N12: =IF(AV12=0,"",VLOOKUP(AV12,skillbasedata!A:B,2,TRUE)) | O12: =BA12 -> 0 | P12: =IF(AW12=0,"",VLOOKUP(AW12,skillbasedata!A:B,2,TRUE)) | Q12: =BB12 -> 0 | R12: =IF(AX12=0,"",VLOOKUP(AX12,skillbasedata!A:B,2,TRUE)) | S12: =BC12 -> 0 | T12: =BE12 -> 0 | U12: =BF12 -> 0 | V12: =IF(BG12=0,0,HEX2DEC(BG12)) -> 2 | W12: 0x0C100002 | X12: 1 | Y12: 2 | Z12: 1002 | AA12: 0 | AB12: 0 | AC12: 100 | AD12: 300 | AE12: 2 | AF12: 0 | AG12: 0 | AH12: 1 | AI12: 0 | AJ12: 0 | AK12: 0 | AL12: 0 | AM12: 0 | AN12: 0 | AO12: 0 | AP12: 0 | AQ12: 0 | AR12: 0 | AS12: 0 | AT12: 96 | AU12: 0 | AV12: 0 | AW12: 0 | AX12: 0 | AY12: 1 | AZ12: 0 | BA12: 0 | BB12: 0 | BC12: 0 | BD12: 0x00000000 | BE12: 0 | BF12: 0 | BG12: =MID(W12,7,4) -> 0002
A13: =IF(X13=0,0,HEX2DEC(MID(W13,5,1))) -> 2 | B13: =IF(X13=0,"",VLOOKUP(Y13,seriesName!A:B,2,TRUE)) -> 皮制 | C13: =IF(A13=1,VLOOKUP(V13,Head!A:B,2,TRUE),IF(A13=2,VLOOKUP(V13,Chest!A:B,2,TRUE),IF(A13=3,VLOOKUP(V13,Arm!A:B,2,TRUE),IF(A13=4,VLOOKUP(V13,Waist!A:B,2,TRUE),IF(A13=5,VLOOKUP(V13,Leg!A:B,2,TRUE),""))))) -> 皮制服饰 | D13: =IF(X13=1,VLOOKUP(AA13,modelID!A:B,2,FALSE),"") -> pl001 | E13: =IF(X13=0,"",AH13+VLOOKUP(AN13,BuildupTable!L:O,4,FALSE)) -> 67 | F13: =AP13 -> 0 | G13: =AQ13 -> 0 | H13: =AR13 -> 0 | I13: =AS13 -> 0 | J13: =IF(AT13=0,"",VLOOKUP(AT13,skillbasedata!A:B,2,TRUE)) -> 植生学 | K13: =AY13 -> 1 | L13: =IF(AU13=0,"",VLOOKUP(AU13,skillbasedata!A:B,2,TRUE)) | M13: =AZ13 -> 0 | N13: =IF(AV13=0,"",VLOOKUP(AV13,skillbasedata!A:B,2,TRUE)) | O13: =BA13 -> 0 | P13: =IF(AW13=0,"",VLOOKUP(AW13,skillbasedata!A:B,2,TRUE)) | Q13: =BB13 -> 0 | R13: =IF(AX13=0,"",VLOOKUP(AX13,skillbasedata!A:B,2,TRUE)) | S13: =BC13 -> 0 | T13: =BE13 -> 0 | U13: =BF13 -> 0 | V13: =IF(BG13=0,0,HEX2DEC(BG13)) -> 2 | W13: 0x0C200002 | X13: 1 | Y13: 2 | Z13: 1002 | AA13: 0 | AB13: 0 | AC13: 100 | AD13: 300 | AE13: 2 | AF13: 0 | AG13: 0 | AH13: 1 | AI13: 0 | AJ13: 0 | AK13: 0 | AL13: 0 | AM13: 0 | AN13: 0 | AO13: 0 | AP13: 0 | AQ13: 0 | AR13: 0 | AS13: 0 | AT13: 79 | AU13: 0 | AV13: 0 | AW13: 0 | AX13: 0 | AY13: 1 | AZ13: 0 | BA13: 0 | BB13: 0 | BC13: 0 | BD13: 0x00000000 | BE13: 0 | BF13: 0 | BG13: =MID(W13,7,4) -> 0002
... A1856: =IF(X1856=0,0,HEX2DEC(MID(W1856,5,1))) -> 5 | B1856: =IF(X1856=0,"",VLOOKUP(Y1856,seriesName!A:B,2,TRUE)) -> 原初 | C1856: =IF(A1856=1,VLOOKUP(V1856,Head!A:B,2,TRUE),IF(A1856=2,VLOOKUP(V1856,Chest!A:B,2,TRUE),IF(A1856=3,VLOOKUP(V1856,Arm!A:B,2,TRUE),IF(A1856=4,VLOOKUP(V1856,Waist!A:B,2,TRUE),IF(A1856=5,VLOOKUP(V1856,Leg!A:B,2,TRUE),""))))) -> 原初护腿 | D1856: =IF(X1856=1,VLOOKUP(AA1856,modelID!A:B,2,FALSE),"") -> pl420 | E1856: =IF(X1856=0,"",AH1856+VLOOKUP(AN1856,BuildupTable!L:O,4,FALSE)) -> 181 | F1856: =AP1856 -> 0 | G1856: =AQ1856 -> 0 | H1856: =AR1856 -> 0 | I1856: =AS1856 -> 2 | J1856: =IF(AT1856=0,"",VLOOKUP(AT1856,skillbasedata!A:B,2,TRUE)) -> 气血觉醒 | K1856: =AY1856 -> 1 | L1856: =IF(AU1856=0,"",VLOOKUP(AU1856,skillbasedata!A:B,2,TRUE)) -> 超会心 | M1856: =AZ1856 -> 1 | N1856: =IF(AV1856=0,"",VLOOKUP(AV1856,skillbasedata!A:B,2,TRUE)) -> 破坏王 | O1856: =BA1856 -> 3 | P1856: =IF(AW1856=0,"",VLOOKUP(AW1856,skillbasedata!A:B,2,TRUE)) | Q1856: =BB1856 -> 0 | R1856: =IF(AX1856=0,"",VLOOKUP(AX1856,skillbasedata!A:B,2,TRUE)) | S1856: =BC1856 -> 0 | T1856: =BE1856 -> 6 | U1856: =BF1856 -> 10 | V1856: =IF(BG1856=0,0,HEX2DEC(BG1856)) -> 502 | W1856: 0x0C5001F6 | X1856: 1 | Y1856: 502 | Z1856: 19601 | AA1856: 238 | AB1856: 9 | AC1856: 30000 | AD1856: 0 | AE1856: 2 | AF1856: 1 | AG1856: 1 | AH1856: 125 | AI1856: -2 | AJ1856: 2 | AK1856: -1 | AL1856: 2 | AM1856: -5 | AN1856: 29 | AO1856: 0 | AP1856: 0 | AQ1856: 0 | AR1856: 0 | AS1856: 2 | AT1856: 144 | AU1856: 7 | AV1856: 81 | AW1856: 0 | AX1856: 0 | AY1856: 1 | AZ1856: 1 | BA1856: 3 | BB1856: 0 | BC1856: 0 | BD1856: 0x00000000 | BE1856: 6 | BF1856: 10 | BG1856: =MID(W1856,7,4) -> 01F6

Sheet BuildupTable
A1: TableTypeEnum | B1: TableType | C1: VillageProgress | D1: HallProgress | E1: MRProgress | F1: LimitLv | G1: LvUpRate | H1: UpVal | I1: Cost | J1: MaxCost | L1: type | M1: enum | N1: LimitLv | O1: maxAddDef
A2: Table01 | B2: 0 | C2: 2 | D2: 2 | E2: 0 | F2: 3 | G2: 1 | H2: 2 | I2: 40 | J2: 0 | L2: 0 | M2: Table01 | N2: =_xlfn.MAXIFS(F:F,B:B,L2) -> 34 | O2: =IF(N2>0,(N2-1)*2,0) -> 66
A3: Table01 | B3: 0 | C3: 2 | D3: 2 | E3: 0 | F3: 5 | G3: 2 | H3: 2 | I3: 40 | J3: 0 | L3: 1 | M3: Table01_02 | N3: =_xlfn.MAXIFS(F:F,B:B,L3) -> 30 | O3: =IF(N3>0,(N3-1)*2,0) -> 58
A4: Table01 | B4: 0 | C4: 5 | D4: 3 | E4: 0 | F4: 6 | G4: 2 | H4: 2 | I4: 40 | J4: 0 | L4: 2 | M4: Table02 | N4: =_xlfn.MAXIFS(F:F,B:B,L4) -> 27 | O4: =IF(N4>0,(N4-1)*2,0) -> 52
A5: Table01 | B5: 0 | C5: 5 | D5: 3 | E5: 0 | F5: 9 | G5: 5 | H5: 2 | I5: 40 | J5: 0 | L5: 3 | M5: Table02_02 | N5: =_xlfn.MAXIFS(F:F,B:B,L5) -> 26 | O5: =IF(N5>0,(N5-1)*2,0) -> 50
A6: Table01 | B6: 0 | C6: 6 | D6: 4 | E6: 0 | F6: 11 | G6: 5 | H6: 2 | I6: 40 | J6: 0 | L6: 4 | M6: Table03 | N6: =_xlfn.MAXIFS(F:F,B:B,L6) -> 23 | O6: =IF(N6>0,(N6-1)*2,0) -> 44
A7: Table01 | B7: 0 | C7: 0 | D7: 5 | E7: 0 | F7: 14 | G7: 10 | H7: 2 | I7: 40 | J7: 0 | L7: 5 | M7: Table03_02 | N7: =_xlfn.MAXIFS(F:F,B:B,L7) -> 22 | O7: =IF(N7>0,(N7-1)*2,0) -> 42
A8: Table01 | B8: 0 | C8: 0 | D8: 6 | E8: 0 | F8: 16 | G8: 10 | H8: 2 | I8: 40 | J8: 0 | L8: 6 | M8: Table03_03 | N8: =_xlfn.MAXIFS(F:F,B:B,L8) -> 1 | O8: =IF(N8>0,(N8-1)*2,0) -> 0
A9: Table01 | B9: 0 | C9: 0 | D9: 6 | E9: 0 | F9: 17 | G9: 20 | H9: 2 | I9: 40 | J9: 0 | L9: 7 | M9: Table03_04 | N9: =_xlfn.MAXIFS(F:F,B:B,L9) -> 4 | O9: =IF(N9>0,(N9-1)*2,0) -> 6
A10: Table01 | B10: 0 | C10: 0 | D10: 7 | E10: 0 | F10: 19 | G10: 20 | H10: 2 | I10: 40 | J10: 0 | L10: 8 | M10: Table04 | N10: =_xlfn.MAXIFS(F:F,B:B,L10) -> 20 | O10: =IF(N10>0,(N10-1)*2,0) -> 38
A11: Table01 | B11: 0 | C11: 0 | D11: 8 | E11: 0 | F11: 22 | G11: 20 | H11: 2 | I11: 40 | J11: 0 | L11: 9 | M11: Table04_02 | N11: =_xlfn.MAXIFS(F:F,B:B,L11) -> 16 | O11: =IF(N11>0,(N11-1)*2,0) -> 30
A12: Table01 | B12: 0 | C12: 0 | D12: 9 | E12: 0 | F12: 28 | G12: 20 | H12: 2 | I12: 40 | J12: 0 | L12: 10 | M12: Table05 | N12: =_xlfn.MAXIFS(F:F,B:B,L12) -> 16 | O12: =IF(N12>0,(N12-1)*2,0) -> 30
A13: Table01 | B13: 0 | C13: 0 | D13: 9 | E13: 0 | F13: 34 | G13: 40 | H13: 2 | I13: 40 | J13: 0 | L13: 11 | M13: Table05_02 | N13: =_xlfn.MAXIFS(F:F,B:B,L13) -> 11 | O13: =IF(N13>0,(N13-1)*2,0) -> 20
... A34: Table02 | B34: 2 | C34: 0 | D34: 9 | E34: 0 | F34: 22 | G34: 20 | H34: 2 | I34: 80 | J34: 0 | L34: 32 | M34: Table07_06 | N34: =_xlfn.MAXIFS(F:F,B:B,L34) -> 4 | O34: =IF(N34>0,(N34-1)*2,0) -> 6
A35: Table02 | B35: 2 | C35: 0 | D35: 9 | E35: 0 | F35: 27 | G35: 40 | H35: 2 | I35: 80 | J35: 0
A36: Table02_02 | B36: 3 | C36: 5 | D36: 3 | E36: 0 | F36: 2 | G36: 5 | H36: 2 | I36: 100 | J36: 0
A37: Table02_02 | B37: 3 | C37: 5 | D37: 3 | E37: 0 | F37: 5 | G37: 10 | H37: 2 | I37: 100 | J37: 0
A38: Table02_02 | B38: 3 | C38: 6 | D38: 4 | E38: 0 | F38: 7 | G38: 10 | H38: 2 | I38: 100 | J38: 0
A39: Table02_02 | B39: 3 | C39: 0 | D39: 5 | E39: 0 | F39: 8 | G39: 20 | H39: 2 | I39: 100 | J39: 0
A40: Table02_02 | B40: 3 | C40: 0 | D40: 6 | E40: 0 | F40: 10 | G40: 20 | H40: 2 | I40: 100 | J40: 0
A41: Table02_02 | B41: 3 | C41: 0 | D41: 7 | E41: 0 | F41: 12 | G41: 20 | H41: 2 | I41: 100 | J41: 0
A42: Table02_02 | B42: 3 | C42: 0 | D42: 8 | E42: 0 | F42: 14 | G42: 20 | H42: 2 | I42: 100 | J42: 0
A43: Table02_02 | B43: 3 | C43: 0 | D43: 9 | E43: 0 | F43: 19 | G43: 20 | H43: 2 | I43: 100 | J43: 0
A44: Table02_02 | B44: 3 | C44: 0 | D44: 9 | E44: 0 | F44: 26 | G44: 40 | H44: 2 | I44: 100 | J44: 0
A45: Table03 | B45: 4 | C45: 6 | D45: 4 | E45: 0 | F45: 4 | G45: 10 | H45: 2 | I45: 200 | J45: 0
A46: Table03 | B46: 4 | C46: 6 | D46: 4 | E46: 0 | F46: 5 | G46: 20 | H46: 2 | I46: 200 | J46: 0
... A184: Table10 | B184: 32 | C184: 0 | D184: 7 | E184: 0 | F184: 4 | G184: 20 | H184: 2 | I184: 300 | J184: 0

Sheet skillbasedata
A1: ID | B1: LookUpName | C1: MaxLevel | D1: IconColor | E1: _CategoryId_1 | F1: _CategoryId_2 | G1: _CategoryId_3 | J1: 描述
A2: 0 | H2: Pl_EquipSkill_None
A3: 1 | B3: 攻击 | C3: 7 | D3: 7 | E3: 3 | F3: 0 | G3: 0 | H3: Pl_EquipSkill_000
A4: 2 | B4: 挑战者 | C4: 5 | D4: 7 | E4: 3 | F4: 4 | G4: 0 | H4: Pl_EquipSkill_001
A5: 3 | B5: 无伤 | C5: 3 | D5: 7 | E5: 3 | F5: 0 | G5: 0 | H5: Pl_EquipSkill_002
A6: 4 | B6: 怨恨 | C6: 5 | D6: 6 | E6: 3 | F6: 0 | G6: 0 | H6: Pl_EquipSkill_003
A7: 5 | B7: 死里逃生 | C7: 3 | D7: 6 | E7: 3 | F7: 0 | G7: 0 | H7: Pl_EquipSkill_004
A8: 6 | B8: 看破 | C8: 7 | D8: 3 | E8: 4 | F8: 0 | G8: 0 | H8: Pl_EquipSkill_005
A9: 7 | B9: 超会心 | C9: 3 | D9: 3 | E9: 4 | F9: 0 | G9: 0 | H9: Pl_EquipSkill_006
A10: 8 | B10: 弱点特效 | C10: 3 | D10: 3 | E10: 4 | F10: 0 | G10: 0 | H10: Pl_EquipSkill_007
A11: 9 | B11: 力量解放 | C11: 5 | D11: 3 | E11: 4 | F11: 7 | G11: 0 | H11: Pl_EquipSkill_008
A12: 10 | B12: 精神抖擞 | C12: 3 | D12: 3 | E12: 4 | F12: 0 | G12: 0 | H12: Pl_EquipSkill_009
A13: 11 | B13: 会心击【属性】 | C13: 3 | D13: 10 | E13: 5 | F13: 0 | G13: 0 | H13: Pl_EquipSkill_010
A14: 12 | B14: 达人艺 | C14: 3 | D14: 1 | E14: 1 | F14: 0 | G14: 0 | H14: Pl_EquipSkill_011
... A149: 147 | B149: 激励 | C149: 1 | D149: 1 | E149: 15 | F149: 3 | G149: 0 | H149: Pl_EquipSkill_235

Sheet seriesName
A1: 0 | B1: 炎火装束
A2: 1 | B2: 炎火装束・霸
A3: 2 | B3: 皮制
A4: 3 | B4: 皮制S
A5: 4 | B5: 锁甲
A6: 5 | B6: 锁甲S
A7: 6 | B7: 猎人
A8: 7 | B8: 猎人S
A9: 8 | B9: 杜宾
A10: 9 | B10: 合金
A11: 10 | B11: 合金S
A12: 11 | B12: 铸铁
... A472: 471 | B472: <COLOR FF0000>#Rejected#</COLOR> ArmorSeries_Hunter_471
A473: 472
A474: 473
A475: 474
A476: 475
A477: 476
A478: 477
A479: 478
A480: 479
A481: 480
A482: 481 | B482: 啮生虫王冠
A483: 482 | B483: 蒸汽贵族
A484: 483 | B484: 海豚王冠
A485: 484 | B485: 探明的单片眼镜
A486: 485 | B486: 机械
A487: 486 | B487: 黑翼耳饰
A488: 487 | B488: 牙猎面具
A489: 488 | B489: 白色福木兔耳套
A490: 489 | B490: 红血耳饰
A491: 490 | B491: 黑暗之眼
A492: 491 | B492: 水行・醒
A493: 492 | B493: 脉动钢龙
... A513: 512 | B513: 系列512

Sheet Head
A1: 0 | B1: 炎火装束【头巾】
A2: 1 | B2: 炎火装束【头巾】霸
A3: 2 | B3: 皮制头饰
A4: 3 | B4: 皮制S头饰
A5: 4 | B5: 锁甲头饰
A6: 5 | B6: 锁甲S头饰
A7: 6 | B7: 猎人头盔
A8: 7 | B8: 猎人S头盔
A9: 8 | B9: 杜宾头盔
A10: 9 | B10: 合金头盔
A11: 10 | B11: 合金S头盔
A12: 11 | B12: 铸铁头盔
... A79: 78 | B79: 硬甲龙S头盔
A80: 79
A81: 80
A82: 81 | B82: 飞甲虫礼帽
A83: 82 | B83: 飞甲虫S礼帽
A84: 83 | B84: 野猪伪装
A85: 84 | B85: 野猪S伪装
A86: 85 | B86: 翼蛇龙头饰
A87: 86 | B87: 翼蛇龙S头饰
A88: 87
A89: 88
A90: 89
A91: 90
A92: 91 | B92: 毒狗龙头盔
A93: 92 | B93: 毒狗龙S头盔
A94: 93 | B94: 眠狗龙头盔
A95: 94 | B95: 眠狗龙S头盔
A96: 95 | B96: 青熊兽头盔
A97: 96 | B97: 青熊兽S头盔
A98: 97 | B98: 赤甲兽头盔
A99: 98 | B99: 赤甲兽S头盔
A100: 99 | B100: 水兽头盔
A101: 100 | B101: 水兽S头盔
A102: 101 | B102: 土砂龙头盔
A103: 102 | B103: 土砂龙S头盔
... A133: 132 | B133: 爆鳞龙头盔
A134: 133
A135: 134 | B135: 骷髅头饰
...

Sheet Chest
A1: 0 | B1: 炎火装束【上衣】
A2: 1 | B2: 炎火装束【上衣】霸
A3: 2 | B3: 皮制服饰
A4: 3 | B4: 皮制S服饰
A5: 4 | B5: 锁甲服饰
A6: 5 | B6: 锁甲S服饰
A7: 6 | B7: 猎人铠甲
A8: 7 | B8: 猎人S铠甲
A9: 8 | B9: 杜宾铠甲
A10: 9 | B10: 合金铠甲
A11: 10 | B11: 合金S铠甲
A12: 11 | B12: 铸铁铠甲
... A73: 72 | B73: 帝王铠甲
A74: 73
A75: 74
A76: 75 | B76: 垂皮龙披风
A77: 76 | B77: 垂皮龙S披风
A78: 77 | B78: 硬甲龙铠甲
A79: 78 | B79: 硬甲龙S铠甲
A80: 79
A81: 80
A82: 81 | B82: 飞甲虫服装
A83: 82 | B83: 飞甲虫S服装
A84: 83
A85: 84
A86: 85 | B86: 翼蛇龙套装衣装
A87: 86 | B87: 翼蛇龙套装S衣装
A88: 87 | B88: 水生兽铠甲
A89: 88 | B89: 水生兽S铠甲
A90: 89 | B90: 熔岩兽铠甲
A91: 90 | B91: 熔岩兽S铠甲
A92: 91 | B92: 毒狗龙铠甲
A93: 92 | B93: 毒狗龙S铠甲
A94: 93 | B94: 眠狗龙铠甲
A95: 94 | B95: 眠狗龙S铠甲
A96: 95 | B96: 青熊兽铠甲
A97: 96 | B97: 青熊兽S铠甲
... A133: 132 | B133: 爆鳞龙铠甲
A134: 133
A135: 134
...

Sheet Arm
A1: 0 | B1: 炎火装束【手甲】
A2: 1 | B2: 炎火装束【手甲】霸
A3: 2 | B3: 皮制手套
A4: 3 | B4: 皮制S手套
A5: 4 | B5: 锁甲手套
A6: 5 | B6: 锁甲S手套
A7: 6 | B7: 猎人腕甲
A8: 7 | B8: 猎人S腕甲
A9: 8 | B9: 杜宾腕甲
A10: 9 | B10: 合金腕甲
A11: 10 | B11: 合金S腕甲
A12: 11 | B12: 铸铁腕甲
... A30: 29 | B30: 海境S腕甲
A31: 30
A32: 31
A33: 32 | B33: 雪绒花枝叶
A34: 33 | B34: 雪绒花S枝叶
A35: 34 | B35: 毒蝎护袖
A36: 35 | B36: 毒蝎S护袖
A37: 36 | B37: 毒蛛护袖
A38: 37 | B38: 毒蛛S护袖
A39: 38 | B39: 倪泰表【手甲】
A40: 39 | B40: 倪泰表【手甲】霸
A41: 40 | B41: 神凪【花袖】
A42: 41 | B42: 神凪・愿【花袖】
A43: 42 | B43: 倪泰里【手甲】
A44: 43 | B44: 倪泰里【手甲】霸
... A73: 72 | B73: 帝王腕甲
A74: 73
A75: 74
A76: 75
A77: 76
A78: 77 | B78: 硬甲龙腕甲
A79: 78 | B79: 硬甲龙S腕甲
A80: 79 | B80: 狗龙皮臂甲
A81: 80 | B81: 狗龙皮臂甲S
A82: 81 | B82: 飞甲虫护手
A83: 82 | B83: 飞甲虫S护手
A84: 83
A85: 84
...

Sheet Waist
A1: 0 | B1: 炎火装束【腰卷】
A2: 1 | B2: 炎火装束【腰卷】霸
A3: 2 | B3: 皮制腰带
A4: 3 | B4: 皮制S腰带
A5: 4 | B5: 锁甲腰带
A6: 5 | B6: 锁甲S腰带
A7: 6 | B7: 猎人腰甲
A8: 7 | B8: 猎人S腰甲
A9: 8 | B9: 杜宾腰甲
A10: 9 | B10: 合金腰甲
A11: 10 | B11: 合金S腰甲
A12: 11 | B12: 铸铁腰甲
... A30: 29 | B30: 海境S腰甲
A31: 30
A32: 31
A33: 32 | B33: 雪绒花叶片
A34: 33 | B34: 雪绒花S叶片
A35: 34 | B35: 毒蝎护腰具
A36: 35 | B36: 毒蝎S护腰具
A37: 36 | B37: 毒蛛护腰具
A38: 37 | B38: 毒蛛S护腰具
A39: 38 | B39: 倪泰表【腰卷】
A40: 39 | B40: 倪泰表【腰卷】霸
A41: 40 | B41: 神凪【腰卷】
A42: 41 | B42: 神凪・愿【腰卷】
A43: 42 | B43: 倪泰里【腰卷】
A44: 43 | B44: 倪泰里【腰卷】霸
... A73: 72 | B73: 帝王腰甲
A74: 73
A75: 74
A76: 75
A77: 76
A78: 77 | B78: 硬甲龙腰甲
A79: 78 | B79: 硬甲龙S腰甲
A80: 79
A81: 80
A82: 81 | B82: 飞甲虫腰甲
A83: 82 | B83: 飞甲虫S腰甲
A84: 83
A85: 84
...

Sheet Leg
A1: 0 | B1: 炎火装束【绑腿】
A2: 1 | B2: 炎火装束【绑腿】霸
A3: 2 | B3: 皮制长裤
A4: 3 | B4: 皮制S长裤
A5: 4 | B5: 锁甲长裤
A6: 5 | B6: 锁甲S长裤
A7: 6 | B7: 猎人护腿
A8: 7 | B8: 猎人S护腿
A9: 8 | B9: 杜宾护腿
A10: 9 | B10: 合金护腿
A11: 10 | B11: 合金S护腿
A12: 11 | B12: 铸铁护腿
... A30: 29 | B30: 海境S护腿
A31: 30
A32: 31
A33: 32 | B33: 雪绒花扎根
A34: 33 | B34: 雪绒花S扎根
A35: 34 | B35: 毒蝎脚
A36: 35 | B36: 毒蝎S脚
A37: 36 | B37: 毒蛛脚
A38: 37 | B38: 毒蛛S脚
A39: 38 | B39: 倪泰表【绑腿】
A40: 39 | B40: 倪泰表【绑腿】霸
A41: 40 | B41: 神凪【绯袴】
A42: 41 | B42: 神凪・愿【绯袴】
A43: 42 | B43: 倪泰里【绑腿】
A44: 43 | B44: 倪泰里【绑腿】霸
... A73: 72 | B73: 帝王护腿
A74: 73
A75: 74
A76: 75
A77: 76
A78: 77 | B78: 硬甲龙护腿
A79: 78 | B79: 硬甲龙S护腿
A80: 79 | B80: 狗龙皮护腿
A81: 80 | B81: 狗龙皮护腿S
A82: 81 | B82: 飞甲虫靴
A83: 82 | B83: 飞甲虫S靴
A84: 83
A85: 84
...

Sheet modelID
A1: 0 | B1: pl001
A2: 1 | B2: pl002
A3: 2 | B3: pl003
A4: 3 | B4: pl004
A5: 4 | B5: pl009
A6: 5 | B6: pl010
A7: 6 | B7: pl011
A8: 7 | B8: pl012
A9: 8 | B9: pl013
A10: 9 | B10: pl014
A11: 10 | B11: pl020
A12: 11 | B12: pl021
... A267: 266 | B267: Error

Sheet armorBaseData(Raw)
A1: lookup_Series | B1: SkillLookUp[0] | C1: SkillLookUp[[1] | D1: SkillLookUp[[2] | E1: SkillLookUp[[3] | F1: SkillLookUp[[4] | G1: Id | H1: IsValid | I1: Series | J1: SortId | K1: ModelId | L1: Rare | M1: Value | N1: BuyValue | O1: SexualEquipable | P1: SymbolColor1 | Q1: SymbolColor2 | R1: DefVal | S1: FireRegVal | T1: WaterRegVal | U1: IceRegVal | V1: ThunderRegVal | W1: DragonRegVal | X1: BuildupTable | Y1: BuffFormula | Z1: DecorationsNumList[0] | AA1: DecorationsNumList[1] | AB1: DecorationsNumList[2] | AC1: SkillList[0] | AD1: SkillList[1] | AE1: SkillList[2] | AF1: SkillList[3] | AG1: SkillList[4] | AH1: SkillLvList[0] | AI1: SkillLvList[1] | AJ1: SkillLvList[2] | AK1: SkillLvList[3] | AL1: SkillLvList[4] | AM1: IdAfterExChange
A2: =IF(H2=0,"",VLOOKUP(I2,seriesName!A:B,2,TRUE)) -> 炎火装束 | B2: =IF(AC2=0,"",VLOOKUP(AC2,skillbasedata!A:B,2,TRUE)) -> 精灵加护 | C2: =IF(AD2=0,"",VLOOKUP(AD2,skillbasedata!A:B,2,TRUE)) | D2: =IF(AE2=0,"",VLOOKUP(AE2,skillbasedata!A:B,2,TRUE)) | E2: =IF(AF2=0,"",VLOOKUP(AF2,skillbasedata!A:B,2,TRUE)) | F2: =IF(AG2=0,"",VLOOKUP(AG2,skillbasedata!A:B,2,TRUE)) | G2: 0x0C100000 | H2: 1 | I2: 0 | J2: 1001 | K2: 30 | L2: 0 | M2: 100 | N2: 300 | O2: 2 | P2: 0 | Q2: 0 | R2: 1 | S2: 1 | T2: 0 | U2: 0 | V2: 0 | W2: 0 | X2: 0 | Y2: 0 | Z2: 0 | AA2: 0 | AB2: 0 | AC2: 57 | AD2: 0 | AE2: 0 | AF2: 0 | AG2: 0 | AH2: 1 | AI2: 0 | AJ2: 0 | AK2: 0 | AL2: 0 | AM2: 0x00000000
A3: =IF(H3=0,"",VLOOKUP(I3,seriesName!A:B,2,TRUE)) -> 炎火装束 | B3: =IF(AC3=0,"",VLOOKUP(AC3,skillbasedata!A:B,2,TRUE)) -> 翔虫使 | C3: =IF(AD3=0,"",VLOOKUP(AD3,skillbasedata!A:B,2,TRUE)) | D3: =IF(AE3=0,"",VLOOKUP(AE3,skillbasedata!A:B,2,TRUE)) | E3: =IF(AF3=0,"",VLOOKUP(AF3,skillbasedata!A:B,2,TRUE)) | F3: =IF(AG3=0,"",VLOOKUP(AG3,skillbasedata!A:B,2,TRUE)) | G3: 0x0C200000 | H3: 1 | I3: 0 | J3: 1001 | K3: 30 | L3: 0 | M3: 100 | N3: 300 | O3: 2 | P3: 0 | Q3: 0 | R3: 1 | S3: 1 | T3: 0 | U3: 0 | V3: 0 | W3: 0 | X3: 0 | Y3: 0 | Z3: 0 | AA3: 0 | AB3: 0 | AC3: 104 | AD3: 0 | AE3: 0 | AF3: 0 | AG3: 0 | AH3: 1 | AI3: 0 | AJ3: 0 | AK3: 0 | AL3: 0 | AM3: 0x00000000
A4: =IF(H4=0,"",VLOOKUP(I4,seriesName!A:B,2,TRUE)) -> 炎火装束 | B4: =IF(AC4=0,"",VLOOKUP(AC4,skillbasedata!A:B,2,TRUE)) -> 火场怪力 | C4: =IF(AD4=0,"",VLOOKUP(AD4,skillbasedata!A:B,2,TRUE)) | D4: =IF(AE4=0,"",VLOOKUP(AE4,skillbasedata!A:B,2,TRUE)) | E4: =IF(AF4=0,"",VLOOKUP(AF4,skillbasedata!A:B,2,TRUE)) | F4: =IF(AG4=0,"",VLOOKUP(AG4,skillbasedata!A:B,2,TRUE)) | G4: 0x0C300000 | H4: 1 | I4: 0 | J4: 1001 | K4: 30 | L4: 0 | M4: 100 | N4: 300 | O4: 2 | P4: 0 | Q4: 0 | R4: 1 | S4: 1 | T4: 0 | U4: 0 | V4: 0 | W4: 0 | X4: 0 | Y4: 0 | Z4: 0 | AA4: 0 | AB4: 0 | AC4: 91 | AD4: 0 | AE4: 0 | AF4: 0 | AG4: 0 | AH4: 1 | AI4: 0 | AJ4: 0 | AK4: 0 | AL4: 0 | AM4: 0x00000000
A5: =IF(H5=0,"",VLOOKUP(I5,seriesName!A:B,2,TRUE)) -> 炎火装束 | B5: =IF(AC5=0,"",VLOOKUP(AC5,skillbasedata!A:B,2,TRUE)) -> 看破 | C5: =IF(AD5=0,"",VLOOKUP(AD5,skillbasedata!A:B,2,TRUE)) | D5: =IF(AE5=0,"",VLOOKUP(AE5,skillbasedata!A:B,2,TRUE)) | E5: =IF(AF5=0,"",VLOOKUP(AF5,skillbasedata!A:B,2,TRUE)) | F5: =IF(AG5=0,"",VLOOKUP(AG5,skillbasedata!A:B,2,TRUE)) | G5: 0x0C400000 | H5: 1 | I5: 0 | J5: 1001 | K5: 30 | L5: 0 | M5: 100 | N5: 300 | O5: 2 | P5: 0 | Q5: 0 | R5: 1 | S5: 1 | T5: 0 | U5: 0 | V5: 0 | W5: 0 | X5: 0 | Y5: 0 | Z5: 0 | AA5: 0 | AB5: 0 | AC5: 6 | AD5: 0 | AE5: 0 | AF5: 0 | AG5: 0 | AH5: 1 | AI5: 0 | AJ5: 0 | AK5: 0 | AL5: 0 | AM5: 0x00000000
